# chatGPT 分析报告
## 接下来请你逐文件分析下面的工程[0/22] 请对下面的程序文件做一个概述: C:\Users\Tomoyo\Desktop\lxh\mapper\CollegeMapper.java

该文件是一个Java接口文件，主要定义了对学院信息进行数据库操作的方法。其中，包括查询学院信息、删除学院信息、插入学院信息和更新学院信息等基本操作。其中使用了`com.system.po.College`和`com.system.po.CollegeExample`两个实体类作为参数和返回值类型，使用了`org.apache.ibatis.annotations.Param`注解来指定方法参数名称，使得mapper接口与xml对应起来。

## [1/22] 请对下面的程序文件做一个概述: C:\Users\Tomoyo\Desktop\lxh\mapper\CourseMapper.java

[Local Message] 警告，线程1在执行过程中遭遇问题, Traceback：

```
Traceback (most recent call last):
  File "C:\Users\Tomoyo\Downloads\chatgpt_academic-master\crazy_functions\crazy_utils.py", line 186, in _req_gpt
    gpt_say = predict_no_ui_long_connection(
              ^^^^^^^^^^^^^^^^^^^^^^^^^^^^^^
  File "C:\Users\Tomoyo\Downloads\chatgpt_academic-master\request_llm\bridge_chatgpt.py", line 85, in predict_no_ui_long_connection
    raise RuntimeError("OpenAI拒绝了请求：" + error_msg)
RuntimeError: OpenAI拒绝了请求：{    "error": {        "message": "Rate limit reached for default-gpt-3.5-turbo in organization org-rPNvSW70tLGxHIiUZV8ERzxN on requests per min. Limit: 3 / min. Please try again in 20s. Contact us through our help center at help.openai.com if you continue to have issues. Please add a payment method to your account to increase your rate limit. Visit https://platform.openai.com/account/billing to add a payment method.",        "type": "requests",        "param": null,        "code": null    }}
```

[Local Message] 警告，线程1在执行过程中遭遇问题, Traceback：

```
Traceback (most recent call last):
  File "C:\Users\Tomoyo\Downloads\chatgpt_academic-master\crazy_functions\crazy_utils.py", line 186, in _req_gpt
    gpt_say = predict_no_ui_long_connection(
              ^^^^^^^^^^^^^^^^^^^^^^^^^^^^^^
  File "C:\Users\Tomoyo\Downloads\chatgpt_academic-master\request_llm\bridge_chatgpt.py", line 85, in predict_no_ui_long_connection
    raise RuntimeError("OpenAI拒绝了请求：" + error_msg)
RuntimeError: OpenAI拒绝了请求：{    "error": {        "message": "Rate limit reached for default-gpt-3.5-turbo in organization org-rPNvSW70tLGxHIiUZV8ERzxN on requests per min. Limit: 3 / min. Please try again in 20s. Contact us through our help center at help.openai.com if you continue to have issues. Please add a payment method to your account to increase your rate limit. Visit https://platform.openai.com/account/billing to add a payment method.",        "type": "requests",        "param": null,        "code": null    }}
```

[Local Message] 警告，线程1在执行过程中遭遇问题, Traceback：

```
Traceback (most recent call last):
  File "C:\Users\Tomoyo\Downloads\chatgpt_academic-master\crazy_functions\crazy_utils.py", line 186, in _req_gpt
    gpt_say = predict_no_ui_long_connection(
              ^^^^^^^^^^^^^^^^^^^^^^^^^^^^^^
  File "C:\Users\Tomoyo\Downloads\chatgpt_academic-master\request_llm\bridge_chatgpt.py", line 85, in predict_no_ui_long_connection
    raise RuntimeError("OpenAI拒绝了请求：" + error_msg)
RuntimeError: OpenAI拒绝了请求：{    "error": {        "message": "Rate limit reached for default-gpt-3.5-turbo in organization org-rPNvSW70tLGxHIiUZV8ERzxN on requests per min. Limit: 3 / min. Please try again in 20s. Contact us through our help center at help.openai.com if you continue to have issues. Please add a payment method to your account to increase your rate limit. Visit https://platform.openai.com/account/billing to add a payment method.",        "type": "requests",        "param": null,        "code": null    }}
```



## [2/22] 请对下面的程序文件做一个概述: C:\Users\Tomoyo\Desktop\lxh\mapper\CourseMapperCustom.java

[Local Message] 警告，线程2在执行过程中遭遇问题, Traceback：

```
Traceback (most recent call last):
  File "C:\Users\Tomoyo\Downloads\chatgpt_academic-master\crazy_functions\crazy_utils.py", line 186, in _req_gpt
    gpt_say = predict_no_ui_long_connection(
              ^^^^^^^^^^^^^^^^^^^^^^^^^^^^^^
  File "C:\Users\Tomoyo\Downloads\chatgpt_academic-master\request_llm\bridge_chatgpt.py", line 85, in predict_no_ui_long_connection
    raise RuntimeError("OpenAI拒绝了请求：" + error_msg)
RuntimeError: OpenAI拒绝了请求：{    "error": {        "message": "Rate limit reached for default-gpt-3.5-turbo in organization org-rPNvSW70tLGxHIiUZV8ERzxN on requests per min. Limit: 3 / min. Please try again in 20s. Contact us through our help center at help.openai.com if you continue to have issues. Please add a payment method to your account to increase your rate limit. Visit https://platform.openai.com/account/billing to add a payment method.",        "type": "requests",        "param": null,        "code": null    }}
```

[Local Message] 警告，线程2在执行过程中遭遇问题, Traceback：

```
Traceback (most recent call last):
  File "C:\Users\Tomoyo\Downloads\chatgpt_academic-master\crazy_functions\crazy_utils.py", line 186, in _req_gpt
    gpt_say = predict_no_ui_long_connection(
              ^^^^^^^^^^^^^^^^^^^^^^^^^^^^^^
  File "C:\Users\Tomoyo\Downloads\chatgpt_academic-master\request_llm\bridge_chatgpt.py", line 85, in predict_no_ui_long_connection
    raise RuntimeError("OpenAI拒绝了请求：" + error_msg)
RuntimeError: OpenAI拒绝了请求：{    "error": {        "message": "Rate limit reached for default-gpt-3.5-turbo in organization org-rPNvSW70tLGxHIiUZV8ERzxN on requests per min. Limit: 3 / min. Please try again in 20s. Contact us through our help center at help.openai.com if you continue to have issues. Please add a payment method to your account to increase your rate limit. Visit https://platform.openai.com/account/billing to add a payment method.",        "type": "requests",        "param": null,        "code": null    }}
```

[Local Message] 警告，线程2在执行过程中遭遇问题, Traceback：

```
Traceback (most recent call last):
  File "C:\Users\Tomoyo\Downloads\chatgpt_academic-master\crazy_functions\crazy_utils.py", line 186, in _req_gpt
    gpt_say = predict_no_ui_long_connection(
              ^^^^^^^^^^^^^^^^^^^^^^^^^^^^^^
  File "C:\Users\Tomoyo\Downloads\chatgpt_academic-master\request_llm\bridge_chatgpt.py", line 85, in predict_no_ui_long_connection
    raise RuntimeError("OpenAI拒绝了请求：" + error_msg)
RuntimeError: OpenAI拒绝了请求：{    "error": {        "message": "Rate limit reached for default-gpt-3.5-turbo in organization org-rPNvSW70tLGxHIiUZV8ERzxN on requests per min. Limit: 3 / min. Please try again in 20s. Contact us through our help center at help.openai.com if you continue to have issues. Please add a payment method to your account to increase your rate limit. Visit https://platform.openai.com/account/billing to add a payment method.",        "type": "requests",        "param": null,        "code": null    }}
```



## [3/22] 请对下面的程序文件做一个概述: C:\Users\Tomoyo\Desktop\lxh\mapper\RoleMapper.java

[Local Message] 警告，线程3在执行过程中遭遇问题, Traceback：

```
Traceback (most recent call last):
  File "C:\Users\Tomoyo\Downloads\chatgpt_academic-master\crazy_functions\crazy_utils.py", line 186, in _req_gpt
    gpt_say = predict_no_ui_long_connection(
              ^^^^^^^^^^^^^^^^^^^^^^^^^^^^^^
  File "C:\Users\Tomoyo\Downloads\chatgpt_academic-master\request_llm\bridge_chatgpt.py", line 85, in predict_no_ui_long_connection
    raise RuntimeError("OpenAI拒绝了请求：" + error_msg)
RuntimeError: OpenAI拒绝了请求：{    "error": {        "message": "Rate limit reached for default-gpt-3.5-turbo in organization org-rPNvSW70tLGxHIiUZV8ERzxN on requests per min. Limit: 3 / min. Please try again in 20s. Contact us through our help center at help.openai.com if you continue to have issues. Please add a payment method to your account to increase your rate limit. Visit https://platform.openai.com/account/billing to add a payment method.",        "type": "requests",        "param": null,        "code": null    }}
```

[Local Message] 警告，线程3在执行过程中遭遇问题, Traceback：

```
Traceback (most recent call last):
  File "C:\Users\Tomoyo\Downloads\chatgpt_academic-master\crazy_functions\crazy_utils.py", line 186, in _req_gpt
    gpt_say = predict_no_ui_long_connection(
              ^^^^^^^^^^^^^^^^^^^^^^^^^^^^^^
  File "C:\Users\Tomoyo\Downloads\chatgpt_academic-master\request_llm\bridge_chatgpt.py", line 85, in predict_no_ui_long_connection
    raise RuntimeError("OpenAI拒绝了请求：" + error_msg)
RuntimeError: OpenAI拒绝了请求：{    "error": {        "message": "Rate limit reached for default-gpt-3.5-turbo in organization org-rPNvSW70tLGxHIiUZV8ERzxN on requests per min. Limit: 3 / min. Please try again in 20s. Contact us through our help center at help.openai.com if you continue to have issues. Please add a payment method to your account to increase your rate limit. Visit https://platform.openai.com/account/billing to add a payment method.",        "type": "requests",        "param": null,        "code": null    }}
```

[Local Message] 警告，线程3在执行过程中遭遇问题, Traceback：

```
Traceback (most recent call last):
  File "C:\Users\Tomoyo\Downloads\chatgpt_academic-master\crazy_functions\crazy_utils.py", line 186, in _req_gpt
    gpt_say = predict_no_ui_long_connection(
              ^^^^^^^^^^^^^^^^^^^^^^^^^^^^^^
  File "C:\Users\Tomoyo\Downloads\chatgpt_academic-master\request_llm\bridge_chatgpt.py", line 85, in predict_no_ui_long_connection
    raise RuntimeError("OpenAI拒绝了请求：" + error_msg)
RuntimeError: OpenAI拒绝了请求：{    "error": {        "message": "Rate limit reached for default-gpt-3.5-turbo in organization org-rPNvSW70tLGxHIiUZV8ERzxN on requests per min. Limit: 3 / min. Please try again in 20s. Contact us through our help center at help.openai.com if you continue to have issues. Please add a payment method to your account to increase your rate limit. Visit https://platform.openai.com/account/billing to add a payment method.",        "type": "requests",        "param": null,        "code": null    }}
```



## [4/22] 请对下面的程序文件做一个概述: C:\Users\Tomoyo\Desktop\lxh\mapper\SelectedcourseMapper.java

该文件是一个Java接口文件，位于com.system.mapper包内。该接口定义了与实体类Selectedcourse和SelectedcourseExample有关的增删改查方法，用于与数据库进行交互操作。其中包括countByExample、deleteByExample、insert、insertSelective、selectByExample、updateByExampleSelective和updateByExample方法。该接口采用了MyBatis框架的注解方式来映射SQL语句。

## [5/22] 请对下面的程序文件做一个概述: C:\Users\Tomoyo\Desktop\lxh\mapper\StudentMapper.java

[Local Message] 警告，线程5在执行过程中遭遇问题, Traceback：

```
Traceback (most recent call last):
  File "C:\Users\Tomoyo\Downloads\chatgpt_academic-master\crazy_functions\crazy_utils.py", line 186, in _req_gpt
    gpt_say = predict_no_ui_long_connection(
              ^^^^^^^^^^^^^^^^^^^^^^^^^^^^^^
  File "C:\Users\Tomoyo\Downloads\chatgpt_academic-master\request_llm\bridge_chatgpt.py", line 85, in predict_no_ui_long_connection
    raise RuntimeError("OpenAI拒绝了请求：" + error_msg)
RuntimeError: OpenAI拒绝了请求：{    "error": {        "message": "Rate limit reached for default-gpt-3.5-turbo in organization org-rPNvSW70tLGxHIiUZV8ERzxN on requests per min. Limit: 3 / min. Please try again in 20s. Contact us through our help center at help.openai.com if you continue to have issues. Please add a payment method to your account to increase your rate limit. Visit https://platform.openai.com/account/billing to add a payment method.",        "type": "requests",        "param": null,        "code": null    }}
```

[Local Message] 警告，线程5在执行过程中遭遇问题, Traceback：

```
Traceback (most recent call last):
  File "C:\Users\Tomoyo\Downloads\chatgpt_academic-master\crazy_functions\crazy_utils.py", line 186, in _req_gpt
    gpt_say = predict_no_ui_long_connection(
              ^^^^^^^^^^^^^^^^^^^^^^^^^^^^^^
  File "C:\Users\Tomoyo\Downloads\chatgpt_academic-master\request_llm\bridge_chatgpt.py", line 85, in predict_no_ui_long_connection
    raise RuntimeError("OpenAI拒绝了请求：" + error_msg)
RuntimeError: OpenAI拒绝了请求：{    "error": {        "message": "Rate limit reached for default-gpt-3.5-turbo in organization org-rPNvSW70tLGxHIiUZV8ERzxN on requests per min. Limit: 3 / min. Please try again in 20s. Contact us through our help center at help.openai.com if you continue to have issues. Please add a payment method to your account to increase your rate limit. Visit https://platform.openai.com/account/billing to add a payment method.",        "type": "requests",        "param": null,        "code": null    }}
```

[Local Message] 警告，线程5在执行过程中遭遇问题, Traceback：

```
Traceback (most recent call last):
  File "C:\Users\Tomoyo\Downloads\chatgpt_academic-master\crazy_functions\crazy_utils.py", line 186, in _req_gpt
    gpt_say = predict_no_ui_long_connection(
              ^^^^^^^^^^^^^^^^^^^^^^^^^^^^^^
  File "C:\Users\Tomoyo\Downloads\chatgpt_academic-master\request_llm\bridge_chatgpt.py", line 85, in predict_no_ui_long_connection
    raise RuntimeError("OpenAI拒绝了请求：" + error_msg)
RuntimeError: OpenAI拒绝了请求：{    "error": {        "message": "Rate limit reached for default-gpt-3.5-turbo in organization org-rPNvSW70tLGxHIiUZV8ERzxN on requests per min. Limit: 3 / min. Please try again in 20s. Contact us through our help center at help.openai.com if you continue to have issues. Please add a payment method to your account to increase your rate limit. Visit https://platform.openai.com/account/billing to add a payment method.",        "type": "requests",        "param": null,        "code": null    }}
```



## [6/22] 请对下面的程序文件做一个概述: C:\Users\Tomoyo\Desktop\lxh\mapper\StudentMapperCustom.java

[Local Message] 警告，线程6在执行过程中遭遇问题, Traceback：

```
Traceback (most recent call last):
  File "C:\Users\Tomoyo\Downloads\chatgpt_academic-master\crazy_functions\crazy_utils.py", line 186, in _req_gpt
    gpt_say = predict_no_ui_long_connection(
              ^^^^^^^^^^^^^^^^^^^^^^^^^^^^^^
  File "C:\Users\Tomoyo\Downloads\chatgpt_academic-master\request_llm\bridge_chatgpt.py", line 85, in predict_no_ui_long_connection
    raise RuntimeError("OpenAI拒绝了请求：" + error_msg)
RuntimeError: OpenAI拒绝了请求：{    "error": {        "message": "Rate limit reached for default-gpt-3.5-turbo in organization org-rPNvSW70tLGxHIiUZV8ERzxN on requests per min. Limit: 3 / min. Please try again in 20s. Contact us through our help center at help.openai.com if you continue to have issues. Please add a payment method to your account to increase your rate limit. Visit https://platform.openai.com/account/billing to add a payment method.",        "type": "requests",        "param": null,        "code": null    }}
```

[Local Message] 警告，线程6在执行过程中遭遇问题, Traceback：

```
Traceback (most recent call last):
  File "C:\Users\Tomoyo\Downloads\chatgpt_academic-master\crazy_functions\crazy_utils.py", line 186, in _req_gpt
    gpt_say = predict_no_ui_long_connection(
              ^^^^^^^^^^^^^^^^^^^^^^^^^^^^^^
  File "C:\Users\Tomoyo\Downloads\chatgpt_academic-master\request_llm\bridge_chatgpt.py", line 85, in predict_no_ui_long_connection
    raise RuntimeError("OpenAI拒绝了请求：" + error_msg)
RuntimeError: OpenAI拒绝了请求：{    "error": {        "message": "Rate limit reached for default-gpt-3.5-turbo in organization org-rPNvSW70tLGxHIiUZV8ERzxN on requests per min. Limit: 3 / min. Please try again in 20s. Contact us through our help center at help.openai.com if you continue to have issues. Please add a payment method to your account to increase your rate limit. Visit https://platform.openai.com/account/billing to add a payment method.",        "type": "requests",        "param": null,        "code": null    }}
```

[Local Message] 警告，线程6在执行过程中遭遇问题, Traceback：

```
Traceback (most recent call last):
  File "C:\ProgramData\Anaconda3\envs\gptac_venv\Lib\site-packages\urllib3\connectionpool.py", line 703, in urlopen
    httplib_response = self._make_request(
                       ^^^^^^^^^^^^^^^^^^^
  File "C:\ProgramData\Anaconda3\envs\gptac_venv\Lib\site-packages\urllib3\connectionpool.py", line 386, in _make_request
    self._validate_conn(conn)
  File "C:\ProgramData\Anaconda3\envs\gptac_venv\Lib\site-packages\urllib3\connectionpool.py", line 1042, in _validate_conn
    conn.connect()
  File "C:\ProgramData\Anaconda3\envs\gptac_venv\Lib\site-packages\urllib3\connection.py", line 419, in connect
    self.sock = ssl_wrap_socket(
                ^^^^^^^^^^^^^^^^
  File "C:\ProgramData\Anaconda3\envs\gptac_venv\Lib\site-packages\urllib3\util\ssl_.py", line 449, in ssl_wrap_socket
    ssl_sock = _ssl_wrap_socket_impl(
               ^^^^^^^^^^^^^^^^^^^^^^
  File "C:\ProgramData\Anaconda3\envs\gptac_venv\Lib\site-packages\urllib3\util\ssl_.py", line 493, in _ssl_wrap_socket_impl
    return ssl_context.wrap_socket(sock, server_hostname=server_hostname)
           ^^^^^^^^^^^^^^^^^^^^^^^^^^^^^^^^^^^^^^^^^^^^^^^^^^^^^^^^^^^^^^
  File "C:\ProgramData\Anaconda3\envs\gptac_venv\Lib\ssl.py", line 517, in wrap_socket
    return self.sslsocket_class._create(
           ^^^^^^^^^^^^^^^^^^^^^^^^^^^^^
  File "C:\ProgramData\Anaconda3\envs\gptac_venv\Lib\ssl.py", line 1075, in _create
    self.do_handshake()
  File "C:\ProgramData\Anaconda3\envs\gptac_venv\Lib\ssl.py", line 1346, in do_handshake
    self._sslobj.do_handshake()
ssl.SSLEOFError: [SSL: UNEXPECTED_EOF_WHILE_READING] EOF occurred in violation of protocol (_ssl.c:1002)

During handling of the above exception, another exception occurred:

Traceback (most recent call last):
  File "C:\ProgramData\Anaconda3\envs\gptac_venv\Lib\site-packages\requests\adapters.py", line 489, in send
    resp = conn.urlopen(
           ^^^^^^^^^^^^^
  File "C:\ProgramData\Anaconda3\envs\gptac_venv\Lib\site-packages\urllib3\connectionpool.py", line 787, in urlopen
    retries = retries.increment(
              ^^^^^^^^^^^^^^^^^^
  File "C:\ProgramData\Anaconda3\envs\gptac_venv\Lib\site-packages\urllib3\util\retry.py", line 592, in increment
    raise MaxRetryError(_pool, url, error or ResponseError(cause))
urllib3.exceptions.MaxRetryError: SOCKSHTTPSConnectionPool(host='api.openai.com', port=443): Max retries exceeded with url: /v1/chat/completions (Caused by SSLError(SSLEOFError(8, '[SSL: UNEXPECTED_EOF_WHILE_READING] EOF occurred in violation of protocol (_ssl.c:1002)')))

During handling of the above exception, another exception occurred:

Traceback (most recent call last):
  File "C:\Users\Tomoyo\Downloads\chatgpt_academic-master\crazy_functions\crazy_utils.py", line 186, in _req_gpt
    gpt_say = predict_no_ui_long_connection(
              ^^^^^^^^^^^^^^^^^^^^^^^^^^^^^^
  File "C:\Users\Tomoyo\Downloads\chatgpt_academic-master\request_llm\bridge_chatgpt.py", line 63, in predict_no_ui_long_connection
    response = requests.post(API_URL, headers=headers, proxies=proxies,
               ^^^^^^^^^^^^^^^^^^^^^^^^^^^^^^^^^^^^^^^^^^^^^^^^^^^^^^^^
  File "C:\ProgramData\Anaconda3\envs\gptac_venv\Lib\site-packages\requests\api.py", line 115, in post
    return request("post", url, data=data, json=json, **kwargs)
           ^^^^^^^^^^^^^^^^^^^^^^^^^^^^^^^^^^^^^^^^^^^^^^^^^^^^
  File "C:\ProgramData\Anaconda3\envs\gptac_venv\Lib\site-packages\requests\api.py", line 59, in request
    return session.request(method=method, url=url, **kwargs)
           ^^^^^^^^^^^^^^^^^^^^^^^^^^^^^^^^^^^^^^^^^^^^^^^^^
  File "C:\ProgramData\Anaconda3\envs\gptac_venv\Lib\site-packages\requests\sessions.py", line 587, in request
    resp = self.send(prep, **send_kwargs)
           ^^^^^^^^^^^^^^^^^^^^^^^^^^^^^^
  File "C:\ProgramData\Anaconda3\envs\gptac_venv\Lib\site-packages\requests\sessions.py", line 701, in send
    r = adapter.send(request, **kwargs)
        ^^^^^^^^^^^^^^^^^^^^^^^^^^^^^^^
  File "C:\ProgramData\Anaconda3\envs\gptac_venv\Lib\site-packages\requests\adapters.py", line 563, in send
    raise SSLError(e, request=request)
requests.exceptions.SSLError: SOCKSHTTPSConnectionPool(host='api.openai.com', port=443): Max retries exceeded with url: /v1/chat/completions (Caused by SSLError(SSLEOFError(8, '[SSL: UNEXPECTED_EOF_WHILE_READING] EOF occurred in violation of protocol (_ssl.c:1002)')))
```



## [7/22] 请对下面的程序文件做一个概述: C:\Users\Tomoyo\Desktop\lxh\mapper\TeacherMapper.java

[Local Message] 警告，线程7在执行过程中遭遇问题, Traceback：

```
Traceback (most recent call last):
  File "C:\Users\Tomoyo\Downloads\chatgpt_academic-master\crazy_functions\crazy_utils.py", line 186, in _req_gpt
    gpt_say = predict_no_ui_long_connection(
              ^^^^^^^^^^^^^^^^^^^^^^^^^^^^^^
  File "C:\Users\Tomoyo\Downloads\chatgpt_academic-master\request_llm\bridge_chatgpt.py", line 85, in predict_no_ui_long_connection
    raise RuntimeError("OpenAI拒绝了请求：" + error_msg)
RuntimeError: OpenAI拒绝了请求：{    "error": {        "message": "Rate limit reached for default-gpt-3.5-turbo in organization org-rPNvSW70tLGxHIiUZV8ERzxN on requests per min. Limit: 3 / min. Please try again in 20s. Contact us through our help center at help.openai.com if you continue to have issues. Please add a payment method to your account to increase your rate limit. Visit https://platform.openai.com/account/billing to add a payment method.",        "type": "requests",        "param": null,        "code": null    }}
```

[Local Message] 警告，线程7在执行过程中遭遇问题, Traceback：

```
Traceback (most recent call last):
  File "C:\Users\Tomoyo\Downloads\chatgpt_academic-master\crazy_functions\crazy_utils.py", line 186, in _req_gpt
    gpt_say = predict_no_ui_long_connection(
              ^^^^^^^^^^^^^^^^^^^^^^^^^^^^^^
  File "C:\Users\Tomoyo\Downloads\chatgpt_academic-master\request_llm\bridge_chatgpt.py", line 85, in predict_no_ui_long_connection
    raise RuntimeError("OpenAI拒绝了请求：" + error_msg)
RuntimeError: OpenAI拒绝了请求：{    "error": {        "message": "Rate limit reached for default-gpt-3.5-turbo in organization org-rPNvSW70tLGxHIiUZV8ERzxN on requests per min. Limit: 3 / min. Please try again in 20s. Contact us through our help center at help.openai.com if you continue to have issues. Please add a payment method to your account to increase your rate limit. Visit https://platform.openai.com/account/billing to add a payment method.",        "type": "requests",        "param": null,        "code": null    }}
```

[Local Message] 警告，线程7在执行过程中遭遇问题, Traceback：

```
Traceback (most recent call last):
  File "C:\ProgramData\Anaconda3\envs\gptac_venv\Lib\site-packages\urllib3\connectionpool.py", line 703, in urlopen
    httplib_response = self._make_request(
                       ^^^^^^^^^^^^^^^^^^^
  File "C:\ProgramData\Anaconda3\envs\gptac_venv\Lib\site-packages\urllib3\connectionpool.py", line 386, in _make_request
    self._validate_conn(conn)
  File "C:\ProgramData\Anaconda3\envs\gptac_venv\Lib\site-packages\urllib3\connectionpool.py", line 1042, in _validate_conn
    conn.connect()
  File "C:\ProgramData\Anaconda3\envs\gptac_venv\Lib\site-packages\urllib3\connection.py", line 419, in connect
    self.sock = ssl_wrap_socket(
                ^^^^^^^^^^^^^^^^
  File "C:\ProgramData\Anaconda3\envs\gptac_venv\Lib\site-packages\urllib3\util\ssl_.py", line 449, in ssl_wrap_socket
    ssl_sock = _ssl_wrap_socket_impl(
               ^^^^^^^^^^^^^^^^^^^^^^
  File "C:\ProgramData\Anaconda3\envs\gptac_venv\Lib\site-packages\urllib3\util\ssl_.py", line 493, in _ssl_wrap_socket_impl
    return ssl_context.wrap_socket(sock, server_hostname=server_hostname)
           ^^^^^^^^^^^^^^^^^^^^^^^^^^^^^^^^^^^^^^^^^^^^^^^^^^^^^^^^^^^^^^
  File "C:\ProgramData\Anaconda3\envs\gptac_venv\Lib\ssl.py", line 517, in wrap_socket
    return self.sslsocket_class._create(
           ^^^^^^^^^^^^^^^^^^^^^^^^^^^^^
  File "C:\ProgramData\Anaconda3\envs\gptac_venv\Lib\ssl.py", line 1075, in _create
    self.do_handshake()
  File "C:\ProgramData\Anaconda3\envs\gptac_venv\Lib\ssl.py", line 1346, in do_handshake
    self._sslobj.do_handshake()
ConnectionAbortedError: [WinError 10053] 你的主机中的软件中止了一个已建立的连接。

During handling of the above exception, another exception occurred:

Traceback (most recent call last):
  File "C:\ProgramData\Anaconda3\envs\gptac_venv\Lib\site-packages\requests\adapters.py", line 489, in send
    resp = conn.urlopen(
           ^^^^^^^^^^^^^
  File "C:\ProgramData\Anaconda3\envs\gptac_venv\Lib\site-packages\urllib3\connectionpool.py", line 787, in urlopen
    retries = retries.increment(
              ^^^^^^^^^^^^^^^^^^
  File "C:\ProgramData\Anaconda3\envs\gptac_venv\Lib\site-packages\urllib3\util\retry.py", line 550, in increment
    raise six.reraise(type(error), error, _stacktrace)
          ^^^^^^^^^^^^^^^^^^^^^^^^^^^^^^^^^^^^^^^^^^^^
  File "C:\ProgramData\Anaconda3\envs\gptac_venv\Lib\site-packages\urllib3\packages\six.py", line 769, in reraise
    raise value.with_traceback(tb)
  File "C:\ProgramData\Anaconda3\envs\gptac_venv\Lib\site-packages\urllib3\connectionpool.py", line 703, in urlopen
    httplib_response = self._make_request(
                       ^^^^^^^^^^^^^^^^^^^
  File "C:\ProgramData\Anaconda3\envs\gptac_venv\Lib\site-packages\urllib3\connectionpool.py", line 386, in _make_request
    self._validate_conn(conn)
  File "C:\ProgramData\Anaconda3\envs\gptac_venv\Lib\site-packages\urllib3\connectionpool.py", line 1042, in _validate_conn
    conn.connect()
  File "C:\ProgramData\Anaconda3\envs\gptac_venv\Lib\site-packages\urllib3\connection.py", line 419, in connect
    self.sock = ssl_wrap_socket(
                ^^^^^^^^^^^^^^^^
  File "C:\ProgramData\Anaconda3\envs\gptac_venv\Lib\site-packages\urllib3\util\ssl_.py", line 449, in ssl_wrap_socket
    ssl_sock = _ssl_wrap_socket_impl(
               ^^^^^^^^^^^^^^^^^^^^^^
  File "C:\ProgramData\Anaconda3\envs\gptac_venv\Lib\site-packages\urllib3\util\ssl_.py", line 493, in _ssl_wrap_socket_impl
    return ssl_context.wrap_socket(sock, server_hostname=server_hostname)
           ^^^^^^^^^^^^^^^^^^^^^^^^^^^^^^^^^^^^^^^^^^^^^^^^^^^^^^^^^^^^^^
  File "C:\ProgramData\Anaconda3\envs\gptac_venv\Lib\ssl.py", line 517, in wrap_socket
    return self.sslsocket_class._create(
           ^^^^^^^^^^^^^^^^^^^^^^^^^^^^^
  File "C:\ProgramData\Anaconda3\envs\gptac_venv\Lib\ssl.py", line 1075, in _create
    self.do_handshake()
  File "C:\ProgramData\Anaconda3\envs\gptac_venv\Lib\ssl.py", line 1346, in do_handshake
    self._sslobj.do_handshake()
urllib3.exceptions.ProtocolError: ('Connection aborted.', ConnectionAbortedError(10053, '你的主机中的软件中止了一个已建立的连接。', None, 10053, None))

During handling of the above exception, another exception occurred:

Traceback (most recent call last):
  File "C:\Users\Tomoyo\Downloads\chatgpt_academic-master\crazy_functions\crazy_utils.py", line 186, in _req_gpt
    gpt_say = predict_no_ui_long_connection(
              ^^^^^^^^^^^^^^^^^^^^^^^^^^^^^^
  File "C:\Users\Tomoyo\Downloads\chatgpt_academic-master\request_llm\bridge_chatgpt.py", line 63, in predict_no_ui_long_connection
    response = requests.post(API_URL, headers=headers, proxies=proxies,
               ^^^^^^^^^^^^^^^^^^^^^^^^^^^^^^^^^^^^^^^^^^^^^^^^^^^^^^^^
  File "C:\ProgramData\Anaconda3\envs\gptac_venv\Lib\site-packages\requests\api.py", line 115, in post
    return request("post", url, data=data, json=json, **kwargs)
           ^^^^^^^^^^^^^^^^^^^^^^^^^^^^^^^^^^^^^^^^^^^^^^^^^^^^
  File "C:\ProgramData\Anaconda3\envs\gptac_venv\Lib\site-packages\requests\api.py", line 59, in request
    return session.request(method=method, url=url, **kwargs)
           ^^^^^^^^^^^^^^^^^^^^^^^^^^^^^^^^^^^^^^^^^^^^^^^^^
  File "C:\ProgramData\Anaconda3\envs\gptac_venv\Lib\site-packages\requests\sessions.py", line 587, in request
    resp = self.send(prep, **send_kwargs)
           ^^^^^^^^^^^^^^^^^^^^^^^^^^^^^^
  File "C:\ProgramData\Anaconda3\envs\gptac_venv\Lib\site-packages\requests\sessions.py", line 701, in send
    r = adapter.send(request, **kwargs)
        ^^^^^^^^^^^^^^^^^^^^^^^^^^^^^^^
  File "C:\ProgramData\Anaconda3\envs\gptac_venv\Lib\site-packages\requests\adapters.py", line 547, in send
    raise ConnectionError(err, request=request)
requests.exceptions.ConnectionError: ('Connection aborted.', ConnectionAbortedError(10053, '你的主机中的软件中止了一个已建立的连接。', None, 10053, None))
```



## [8/22] 请对下面的程序文件做一个概述: C:\Users\Tomoyo\Desktop\lxh\mapper\TeacherMapperCustom.java

该程序文件是一个接口文件，文件名为TeacherMapperCustom.java。该接口中定义了两个方法：一个是分页查询老师信息，另一个是获取信息，但是该方法没有具体实现。

## [9/22] 请对下面的程序文件做一个概述: C:\Users\Tomoyo\Desktop\lxh\mapper\UserloginMapper.java

该文件是一个Java接口文件，定义了一个名为UserloginMapper的接口，其中包含了增删改查等对Userlogin表操作的方法。使用了MyBatis框架对数据库进行操作。

## [10/22] 请对下面的程序文件做一个概述: C:\Users\Tomoyo\Desktop\lxh\mapper\UserloginMapperCustom.java

[Local Message] 警告，线程10在执行过程中遭遇问题, Traceback：

```
Traceback (most recent call last):
  File "C:\Users\Tomoyo\Downloads\chatgpt_academic-master\crazy_functions\crazy_utils.py", line 186, in _req_gpt
    gpt_say = predict_no_ui_long_connection(
              ^^^^^^^^^^^^^^^^^^^^^^^^^^^^^^
  File "C:\Users\Tomoyo\Downloads\chatgpt_academic-master\request_llm\bridge_chatgpt.py", line 85, in predict_no_ui_long_connection
    raise RuntimeError("OpenAI拒绝了请求：" + error_msg)
RuntimeError: OpenAI拒绝了请求：{    "error": {        "message": "Rate limit reached for default-gpt-3.5-turbo in organization org-rPNvSW70tLGxHIiUZV8ERzxN on requests per min. Limit: 3 / min. Please try again in 20s. Contact us through our help center at help.openai.com if you continue to have issues. Please add a payment method to your account to increase your rate limit. Visit https://platform.openai.com/account/billing to add a payment method.",        "type": "requests",        "param": null,        "code": null    }}
```

[Local Message] 警告，线程10在执行过程中遭遇问题, Traceback：

```
Traceback (most recent call last):
  File "C:\Users\Tomoyo\Downloads\chatgpt_academic-master\crazy_functions\crazy_utils.py", line 186, in _req_gpt
    gpt_say = predict_no_ui_long_connection(
              ^^^^^^^^^^^^^^^^^^^^^^^^^^^^^^
  File "C:\Users\Tomoyo\Downloads\chatgpt_academic-master\request_llm\bridge_chatgpt.py", line 85, in predict_no_ui_long_connection
    raise RuntimeError("OpenAI拒绝了请求：" + error_msg)
RuntimeError: OpenAI拒绝了请求：{    "error": {        "message": "Rate limit reached for default-gpt-3.5-turbo in organization org-rPNvSW70tLGxHIiUZV8ERzxN on requests per min. Limit: 3 / min. Please try again in 20s. Contact us through our help center at help.openai.com if you continue to have issues. Please add a payment method to your account to increase your rate limit. Visit https://platform.openai.com/account/billing to add a payment method.",        "type": "requests",        "param": null,        "code": null    }}
```

[Local Message] 警告，线程10在执行过程中遭遇问题, Traceback：

```
Traceback (most recent call last):
  File "C:\Users\Tomoyo\Downloads\chatgpt_academic-master\crazy_functions\crazy_utils.py", line 186, in _req_gpt
    gpt_say = predict_no_ui_long_connection(
              ^^^^^^^^^^^^^^^^^^^^^^^^^^^^^^
  File "C:\Users\Tomoyo\Downloads\chatgpt_academic-master\request_llm\bridge_chatgpt.py", line 85, in predict_no_ui_long_connection
    raise RuntimeError("OpenAI拒绝了请求：" + error_msg)
RuntimeError: OpenAI拒绝了请求：{    "error": {        "message": "Rate limit reached for default-gpt-3.5-turbo in organization org-rPNvSW70tLGxHIiUZV8ERzxN on requests per min. Limit: 3 / min. Please try again in 20s. Contact us through our help center at help.openai.com if you continue to have issues. Please add a payment method to your account to increase your rate limit. Visit https://platform.openai.com/account/billing to add a payment method.",        "type": "requests",        "param": null,        "code": null    }}
```



## [11/22] 请对下面的程序文件做一个概述: C:\Users\Tomoyo\Desktop\lxh\mapper\CollegeMapper.xml

此文件是MyBatis框架中的映射文件，用于将Java对象映射到数据库表中的数据。它指定了命名空间、结果集映射、SQL语句和参数类型等内容。具体来说，该文件中包括了一些SQL语句的定义，如select、insert、update和delete等操作，以及一些SQL片段的定义，如where条件和列名等。通过使用该文件，可以让MyBatis框架自动处理大部分的SQL操作，从而简化了持久层的编码工作。

## [12/22] 请对下面的程序文件做一个概述: C:\Users\Tomoyo\Desktop\lxh\mapper\CourseMapper.xml

[Local Message] 警告，线程12在执行过程中遭遇问题, Traceback：

```
Traceback (most recent call last):
  File "C:\ProgramData\Anaconda3\envs\gptac_venv\Lib\site-packages\urllib3\connectionpool.py", line 703, in urlopen
    httplib_response = self._make_request(
                       ^^^^^^^^^^^^^^^^^^^
  File "C:\ProgramData\Anaconda3\envs\gptac_venv\Lib\site-packages\urllib3\connectionpool.py", line 386, in _make_request
    self._validate_conn(conn)
  File "C:\ProgramData\Anaconda3\envs\gptac_venv\Lib\site-packages\urllib3\connectionpool.py", line 1042, in _validate_conn
    conn.connect()
  File "C:\ProgramData\Anaconda3\envs\gptac_venv\Lib\site-packages\urllib3\connection.py", line 419, in connect
    self.sock = ssl_wrap_socket(
                ^^^^^^^^^^^^^^^^
  File "C:\ProgramData\Anaconda3\envs\gptac_venv\Lib\site-packages\urllib3\util\ssl_.py", line 449, in ssl_wrap_socket
    ssl_sock = _ssl_wrap_socket_impl(
               ^^^^^^^^^^^^^^^^^^^^^^
  File "C:\ProgramData\Anaconda3\envs\gptac_venv\Lib\site-packages\urllib3\util\ssl_.py", line 493, in _ssl_wrap_socket_impl
    return ssl_context.wrap_socket(sock, server_hostname=server_hostname)
           ^^^^^^^^^^^^^^^^^^^^^^^^^^^^^^^^^^^^^^^^^^^^^^^^^^^^^^^^^^^^^^
  File "C:\ProgramData\Anaconda3\envs\gptac_venv\Lib\ssl.py", line 517, in wrap_socket
    return self.sslsocket_class._create(
           ^^^^^^^^^^^^^^^^^^^^^^^^^^^^^
  File "C:\ProgramData\Anaconda3\envs\gptac_venv\Lib\ssl.py", line 1075, in _create
    self.do_handshake()
  File "C:\ProgramData\Anaconda3\envs\gptac_venv\Lib\ssl.py", line 1346, in do_handshake
    self._sslobj.do_handshake()
ConnectionResetError: [WinError 10054] 远程主机强迫关闭了一个现有的连接。

During handling of the above exception, another exception occurred:

Traceback (most recent call last):
  File "C:\ProgramData\Anaconda3\envs\gptac_venv\Lib\site-packages\requests\adapters.py", line 489, in send
    resp = conn.urlopen(
           ^^^^^^^^^^^^^
  File "C:\ProgramData\Anaconda3\envs\gptac_venv\Lib\site-packages\urllib3\connectionpool.py", line 787, in urlopen
    retries = retries.increment(
              ^^^^^^^^^^^^^^^^^^
  File "C:\ProgramData\Anaconda3\envs\gptac_venv\Lib\site-packages\urllib3\util\retry.py", line 550, in increment
    raise six.reraise(type(error), error, _stacktrace)
          ^^^^^^^^^^^^^^^^^^^^^^^^^^^^^^^^^^^^^^^^^^^^
  File "C:\ProgramData\Anaconda3\envs\gptac_venv\Lib\site-packages\urllib3\packages\six.py", line 769, in reraise
    raise value.with_traceback(tb)
  File "C:\ProgramData\Anaconda3\envs\gptac_venv\Lib\site-packages\urllib3\connectionpool.py", line 703, in urlopen
    httplib_response = self._make_request(
                       ^^^^^^^^^^^^^^^^^^^
  File "C:\ProgramData\Anaconda3\envs\gptac_venv\Lib\site-packages\urllib3\connectionpool.py", line 386, in _make_request
    self._validate_conn(conn)
  File "C:\ProgramData\Anaconda3\envs\gptac_venv\Lib\site-packages\urllib3\connectionpool.py", line 1042, in _validate_conn
    conn.connect()
  File "C:\ProgramData\Anaconda3\envs\gptac_venv\Lib\site-packages\urllib3\connection.py", line 419, in connect
    self.sock = ssl_wrap_socket(
                ^^^^^^^^^^^^^^^^
  File "C:\ProgramData\Anaconda3\envs\gptac_venv\Lib\site-packages\urllib3\util\ssl_.py", line 449, in ssl_wrap_socket
    ssl_sock = _ssl_wrap_socket_impl(
               ^^^^^^^^^^^^^^^^^^^^^^
  File "C:\ProgramData\Anaconda3\envs\gptac_venv\Lib\site-packages\urllib3\util\ssl_.py", line 493, in _ssl_wrap_socket_impl
    return ssl_context.wrap_socket(sock, server_hostname=server_hostname)
           ^^^^^^^^^^^^^^^^^^^^^^^^^^^^^^^^^^^^^^^^^^^^^^^^^^^^^^^^^^^^^^
  File "C:\ProgramData\Anaconda3\envs\gptac_venv\Lib\ssl.py", line 517, in wrap_socket
    return self.sslsocket_class._create(
           ^^^^^^^^^^^^^^^^^^^^^^^^^^^^^
  File "C:\ProgramData\Anaconda3\envs\gptac_venv\Lib\ssl.py", line 1075, in _create
    self.do_handshake()
  File "C:\ProgramData\Anaconda3\envs\gptac_venv\Lib\ssl.py", line 1346, in do_handshake
    self._sslobj.do_handshake()
urllib3.exceptions.ProtocolError: ('Connection aborted.', ConnectionResetError(10054, '远程主机强迫关闭了一个现有的连接。', None, 10054, None))

During handling of the above exception, another exception occurred:

Traceback (most recent call last):
  File "C:\Users\Tomoyo\Downloads\chatgpt_academic-master\crazy_functions\crazy_utils.py", line 186, in _req_gpt
    gpt_say = predict_no_ui_long_connection(
              ^^^^^^^^^^^^^^^^^^^^^^^^^^^^^^
  File "C:\Users\Tomoyo\Downloads\chatgpt_academic-master\request_llm\bridge_chatgpt.py", line 63, in predict_no_ui_long_connection
    response = requests.post(API_URL, headers=headers, proxies=proxies,
               ^^^^^^^^^^^^^^^^^^^^^^^^^^^^^^^^^^^^^^^^^^^^^^^^^^^^^^^^
  File "C:\ProgramData\Anaconda3\envs\gptac_venv\Lib\site-packages\requests\api.py", line 115, in post
    return request("post", url, data=data, json=json, **kwargs)
           ^^^^^^^^^^^^^^^^^^^^^^^^^^^^^^^^^^^^^^^^^^^^^^^^^^^^
  File "C:\ProgramData\Anaconda3\envs\gptac_venv\Lib\site-packages\requests\api.py", line 59, in request
    return session.request(method=method, url=url, **kwargs)
           ^^^^^^^^^^^^^^^^^^^^^^^^^^^^^^^^^^^^^^^^^^^^^^^^^
  File "C:\ProgramData\Anaconda3\envs\gptac_venv\Lib\site-packages\requests\sessions.py", line 587, in request
    resp = self.send(prep, **send_kwargs)
           ^^^^^^^^^^^^^^^^^^^^^^^^^^^^^^
  File "C:\ProgramData\Anaconda3\envs\gptac_venv\Lib\site-packages\requests\sessions.py", line 701, in send
    r = adapter.send(request, **kwargs)
        ^^^^^^^^^^^^^^^^^^^^^^^^^^^^^^^
  File "C:\ProgramData\Anaconda3\envs\gptac_venv\Lib\site-packages\requests\adapters.py", line 547, in send
    raise ConnectionError(err, request=request)
requests.exceptions.ConnectionError: ('Connection aborted.', ConnectionResetError(10054, '远程主机强迫关闭了一个现有的连接。', None, 10054, None))
```

[Local Message] 警告，线程12在执行过程中遭遇问题, Traceback：

```
Traceback (most recent call last):
  File "C:\Users\Tomoyo\Downloads\chatgpt_academic-master\crazy_functions\crazy_utils.py", line 186, in _req_gpt
    gpt_say = predict_no_ui_long_connection(
              ^^^^^^^^^^^^^^^^^^^^^^^^^^^^^^
  File "C:\Users\Tomoyo\Downloads\chatgpt_academic-master\request_llm\bridge_chatgpt.py", line 85, in predict_no_ui_long_connection
    raise RuntimeError("OpenAI拒绝了请求：" + error_msg)
RuntimeError: OpenAI拒绝了请求：{    "error": {        "message": "Rate limit reached for default-gpt-3.5-turbo in organization org-rPNvSW70tLGxHIiUZV8ERzxN on requests per min. Limit: 3 / min. Please try again in 20s. Contact us through our help center at help.openai.com if you continue to have issues. Please add a payment method to your account to increase your rate limit. Visit https://platform.openai.com/account/billing to add a payment method.",        "type": "requests",        "param": null,        "code": null    }}
```

[Local Message] 警告，线程12在执行过程中遭遇问题, Traceback：

```
Traceback (most recent call last):
  File "C:\Users\Tomoyo\Downloads\chatgpt_academic-master\crazy_functions\crazy_utils.py", line 186, in _req_gpt
    gpt_say = predict_no_ui_long_connection(
              ^^^^^^^^^^^^^^^^^^^^^^^^^^^^^^
  File "C:\Users\Tomoyo\Downloads\chatgpt_academic-master\request_llm\bridge_chatgpt.py", line 85, in predict_no_ui_long_connection
    raise RuntimeError("OpenAI拒绝了请求：" + error_msg)
RuntimeError: OpenAI拒绝了请求：{    "error": {        "message": "Rate limit reached for default-gpt-3.5-turbo in organization org-rPNvSW70tLGxHIiUZV8ERzxN on requests per min. Limit: 3 / min. Please try again in 20s. Contact us through our help center at help.openai.com if you continue to have issues. Please add a payment method to your account to increase your rate limit. Visit https://platform.openai.com/account/billing to add a payment method.",        "type": "requests",        "param": null,        "code": null    }}
```



## [13/22] 请对下面的程序文件做一个概述: C:\Users\Tomoyo\Desktop\lxh\mapper\CourseMapperCustom.xml

[Local Message] 警告，线程13在执行过程中遭遇问题, Traceback：

```
Traceback (most recent call last):
  File "C:\ProgramData\Anaconda3\envs\gptac_venv\Lib\site-packages\urllib3\connectionpool.py", line 703, in urlopen
    httplib_response = self._make_request(
                       ^^^^^^^^^^^^^^^^^^^
  File "C:\ProgramData\Anaconda3\envs\gptac_venv\Lib\site-packages\urllib3\connectionpool.py", line 386, in _make_request
    self._validate_conn(conn)
  File "C:\ProgramData\Anaconda3\envs\gptac_venv\Lib\site-packages\urllib3\connectionpool.py", line 1042, in _validate_conn
    conn.connect()
  File "C:\ProgramData\Anaconda3\envs\gptac_venv\Lib\site-packages\urllib3\connection.py", line 419, in connect
    self.sock = ssl_wrap_socket(
                ^^^^^^^^^^^^^^^^
  File "C:\ProgramData\Anaconda3\envs\gptac_venv\Lib\site-packages\urllib3\util\ssl_.py", line 449, in ssl_wrap_socket
    ssl_sock = _ssl_wrap_socket_impl(
               ^^^^^^^^^^^^^^^^^^^^^^
  File "C:\ProgramData\Anaconda3\envs\gptac_venv\Lib\site-packages\urllib3\util\ssl_.py", line 493, in _ssl_wrap_socket_impl
    return ssl_context.wrap_socket(sock, server_hostname=server_hostname)
           ^^^^^^^^^^^^^^^^^^^^^^^^^^^^^^^^^^^^^^^^^^^^^^^^^^^^^^^^^^^^^^
  File "C:\ProgramData\Anaconda3\envs\gptac_venv\Lib\ssl.py", line 517, in wrap_socket
    return self.sslsocket_class._create(
           ^^^^^^^^^^^^^^^^^^^^^^^^^^^^^
  File "C:\ProgramData\Anaconda3\envs\gptac_venv\Lib\ssl.py", line 1075, in _create
    self.do_handshake()
  File "C:\ProgramData\Anaconda3\envs\gptac_venv\Lib\ssl.py", line 1346, in do_handshake
    self._sslobj.do_handshake()
ConnectionResetError: [WinError 10054] 远程主机强迫关闭了一个现有的连接。

During handling of the above exception, another exception occurred:

Traceback (most recent call last):
  File "C:\ProgramData\Anaconda3\envs\gptac_venv\Lib\site-packages\requests\adapters.py", line 489, in send
    resp = conn.urlopen(
           ^^^^^^^^^^^^^
  File "C:\ProgramData\Anaconda3\envs\gptac_venv\Lib\site-packages\urllib3\connectionpool.py", line 787, in urlopen
    retries = retries.increment(
              ^^^^^^^^^^^^^^^^^^
  File "C:\ProgramData\Anaconda3\envs\gptac_venv\Lib\site-packages\urllib3\util\retry.py", line 550, in increment
    raise six.reraise(type(error), error, _stacktrace)
          ^^^^^^^^^^^^^^^^^^^^^^^^^^^^^^^^^^^^^^^^^^^^
  File "C:\ProgramData\Anaconda3\envs\gptac_venv\Lib\site-packages\urllib3\packages\six.py", line 769, in reraise
    raise value.with_traceback(tb)
  File "C:\ProgramData\Anaconda3\envs\gptac_venv\Lib\site-packages\urllib3\connectionpool.py", line 703, in urlopen
    httplib_response = self._make_request(
                       ^^^^^^^^^^^^^^^^^^^
  File "C:\ProgramData\Anaconda3\envs\gptac_venv\Lib\site-packages\urllib3\connectionpool.py", line 386, in _make_request
    self._validate_conn(conn)
  File "C:\ProgramData\Anaconda3\envs\gptac_venv\Lib\site-packages\urllib3\connectionpool.py", line 1042, in _validate_conn
    conn.connect()
  File "C:\ProgramData\Anaconda3\envs\gptac_venv\Lib\site-packages\urllib3\connection.py", line 419, in connect
    self.sock = ssl_wrap_socket(
                ^^^^^^^^^^^^^^^^
  File "C:\ProgramData\Anaconda3\envs\gptac_venv\Lib\site-packages\urllib3\util\ssl_.py", line 449, in ssl_wrap_socket
    ssl_sock = _ssl_wrap_socket_impl(
               ^^^^^^^^^^^^^^^^^^^^^^
  File "C:\ProgramData\Anaconda3\envs\gptac_venv\Lib\site-packages\urllib3\util\ssl_.py", line 493, in _ssl_wrap_socket_impl
    return ssl_context.wrap_socket(sock, server_hostname=server_hostname)
           ^^^^^^^^^^^^^^^^^^^^^^^^^^^^^^^^^^^^^^^^^^^^^^^^^^^^^^^^^^^^^^
  File "C:\ProgramData\Anaconda3\envs\gptac_venv\Lib\ssl.py", line 517, in wrap_socket
    return self.sslsocket_class._create(
           ^^^^^^^^^^^^^^^^^^^^^^^^^^^^^
  File "C:\ProgramData\Anaconda3\envs\gptac_venv\Lib\ssl.py", line 1075, in _create
    self.do_handshake()
  File "C:\ProgramData\Anaconda3\envs\gptac_venv\Lib\ssl.py", line 1346, in do_handshake
    self._sslobj.do_handshake()
urllib3.exceptions.ProtocolError: ('Connection aborted.', ConnectionResetError(10054, '远程主机强迫关闭了一个现有的连接。', None, 10054, None))

During handling of the above exception, another exception occurred:

Traceback (most recent call last):
  File "C:\Users\Tomoyo\Downloads\chatgpt_academic-master\crazy_functions\crazy_utils.py", line 186, in _req_gpt
    gpt_say = predict_no_ui_long_connection(
              ^^^^^^^^^^^^^^^^^^^^^^^^^^^^^^
  File "C:\Users\Tomoyo\Downloads\chatgpt_academic-master\request_llm\bridge_chatgpt.py", line 63, in predict_no_ui_long_connection
    response = requests.post(API_URL, headers=headers, proxies=proxies,
               ^^^^^^^^^^^^^^^^^^^^^^^^^^^^^^^^^^^^^^^^^^^^^^^^^^^^^^^^
  File "C:\ProgramData\Anaconda3\envs\gptac_venv\Lib\site-packages\requests\api.py", line 115, in post
    return request("post", url, data=data, json=json, **kwargs)
           ^^^^^^^^^^^^^^^^^^^^^^^^^^^^^^^^^^^^^^^^^^^^^^^^^^^^
  File "C:\ProgramData\Anaconda3\envs\gptac_venv\Lib\site-packages\requests\api.py", line 59, in request
    return session.request(method=method, url=url, **kwargs)
           ^^^^^^^^^^^^^^^^^^^^^^^^^^^^^^^^^^^^^^^^^^^^^^^^^
  File "C:\ProgramData\Anaconda3\envs\gptac_venv\Lib\site-packages\requests\sessions.py", line 587, in request
    resp = self.send(prep, **send_kwargs)
           ^^^^^^^^^^^^^^^^^^^^^^^^^^^^^^
  File "C:\ProgramData\Anaconda3\envs\gptac_venv\Lib\site-packages\requests\sessions.py", line 701, in send
    r = adapter.send(request, **kwargs)
        ^^^^^^^^^^^^^^^^^^^^^^^^^^^^^^^
  File "C:\ProgramData\Anaconda3\envs\gptac_venv\Lib\site-packages\requests\adapters.py", line 547, in send
    raise ConnectionError(err, request=request)
requests.exceptions.ConnectionError: ('Connection aborted.', ConnectionResetError(10054, '远程主机强迫关闭了一个现有的连接。', None, 10054, None))
```

[Local Message] 警告，线程13在执行过程中遭遇问题, Traceback：

```
Traceback (most recent call last):
  File "C:\Users\Tomoyo\Downloads\chatgpt_academic-master\crazy_functions\crazy_utils.py", line 186, in _req_gpt
    gpt_say = predict_no_ui_long_connection(
              ^^^^^^^^^^^^^^^^^^^^^^^^^^^^^^
  File "C:\Users\Tomoyo\Downloads\chatgpt_academic-master\request_llm\bridge_chatgpt.py", line 85, in predict_no_ui_long_connection
    raise RuntimeError("OpenAI拒绝了请求：" + error_msg)
RuntimeError: OpenAI拒绝了请求：{    "error": {        "message": "Rate limit reached for default-gpt-3.5-turbo in organization org-rPNvSW70tLGxHIiUZV8ERzxN on requests per min. Limit: 3 / min. Please try again in 20s. Contact us through our help center at help.openai.com if you continue to have issues. Please add a payment method to your account to increase your rate limit. Visit https://platform.openai.com/account/billing to add a payment method.",        "type": "requests",        "param": null,        "code": null    }}
```

[Local Message] 警告，线程13在执行过程中遭遇问题, Traceback：

```
Traceback (most recent call last):
  File "C:\ProgramData\Anaconda3\envs\gptac_venv\Lib\site-packages\urllib3\connectionpool.py", line 703, in urlopen
    httplib_response = self._make_request(
                       ^^^^^^^^^^^^^^^^^^^
  File "C:\ProgramData\Anaconda3\envs\gptac_venv\Lib\site-packages\urllib3\connectionpool.py", line 386, in _make_request
    self._validate_conn(conn)
  File "C:\ProgramData\Anaconda3\envs\gptac_venv\Lib\site-packages\urllib3\connectionpool.py", line 1042, in _validate_conn
    conn.connect()
  File "C:\ProgramData\Anaconda3\envs\gptac_venv\Lib\site-packages\urllib3\connection.py", line 419, in connect
    self.sock = ssl_wrap_socket(
                ^^^^^^^^^^^^^^^^
  File "C:\ProgramData\Anaconda3\envs\gptac_venv\Lib\site-packages\urllib3\util\ssl_.py", line 449, in ssl_wrap_socket
    ssl_sock = _ssl_wrap_socket_impl(
               ^^^^^^^^^^^^^^^^^^^^^^
  File "C:\ProgramData\Anaconda3\envs\gptac_venv\Lib\site-packages\urllib3\util\ssl_.py", line 493, in _ssl_wrap_socket_impl
    return ssl_context.wrap_socket(sock, server_hostname=server_hostname)
           ^^^^^^^^^^^^^^^^^^^^^^^^^^^^^^^^^^^^^^^^^^^^^^^^^^^^^^^^^^^^^^
  File "C:\ProgramData\Anaconda3\envs\gptac_venv\Lib\ssl.py", line 517, in wrap_socket
    return self.sslsocket_class._create(
           ^^^^^^^^^^^^^^^^^^^^^^^^^^^^^
  File "C:\ProgramData\Anaconda3\envs\gptac_venv\Lib\ssl.py", line 1075, in _create
    self.do_handshake()
  File "C:\ProgramData\Anaconda3\envs\gptac_venv\Lib\ssl.py", line 1346, in do_handshake
    self._sslobj.do_handshake()
ConnectionResetError: [WinError 10054] 远程主机强迫关闭了一个现有的连接。

During handling of the above exception, another exception occurred:

Traceback (most recent call last):
  File "C:\ProgramData\Anaconda3\envs\gptac_venv\Lib\site-packages\requests\adapters.py", line 489, in send
    resp = conn.urlopen(
           ^^^^^^^^^^^^^
  File "C:\ProgramData\Anaconda3\envs\gptac_venv\Lib\site-packages\urllib3\connectionpool.py", line 787, in urlopen
    retries = retries.increment(
              ^^^^^^^^^^^^^^^^^^
  File "C:\ProgramData\Anaconda3\envs\gptac_venv\Lib\site-packages\urllib3\util\retry.py", line 550, in increment
    raise six.reraise(type(error), error, _stacktrace)
          ^^^^^^^^^^^^^^^^^^^^^^^^^^^^^^^^^^^^^^^^^^^^
  File "C:\ProgramData\Anaconda3\envs\gptac_venv\Lib\site-packages\urllib3\packages\six.py", line 769, in reraise
    raise value.with_traceback(tb)
  File "C:\ProgramData\Anaconda3\envs\gptac_venv\Lib\site-packages\urllib3\connectionpool.py", line 703, in urlopen
    httplib_response = self._make_request(
                       ^^^^^^^^^^^^^^^^^^^
  File "C:\ProgramData\Anaconda3\envs\gptac_venv\Lib\site-packages\urllib3\connectionpool.py", line 386, in _make_request
    self._validate_conn(conn)
  File "C:\ProgramData\Anaconda3\envs\gptac_venv\Lib\site-packages\urllib3\connectionpool.py", line 1042, in _validate_conn
    conn.connect()
  File "C:\ProgramData\Anaconda3\envs\gptac_venv\Lib\site-packages\urllib3\connection.py", line 419, in connect
    self.sock = ssl_wrap_socket(
                ^^^^^^^^^^^^^^^^
  File "C:\ProgramData\Anaconda3\envs\gptac_venv\Lib\site-packages\urllib3\util\ssl_.py", line 449, in ssl_wrap_socket
    ssl_sock = _ssl_wrap_socket_impl(
               ^^^^^^^^^^^^^^^^^^^^^^
  File "C:\ProgramData\Anaconda3\envs\gptac_venv\Lib\site-packages\urllib3\util\ssl_.py", line 493, in _ssl_wrap_socket_impl
    return ssl_context.wrap_socket(sock, server_hostname=server_hostname)
           ^^^^^^^^^^^^^^^^^^^^^^^^^^^^^^^^^^^^^^^^^^^^^^^^^^^^^^^^^^^^^^
  File "C:\ProgramData\Anaconda3\envs\gptac_venv\Lib\ssl.py", line 517, in wrap_socket
    return self.sslsocket_class._create(
           ^^^^^^^^^^^^^^^^^^^^^^^^^^^^^
  File "C:\ProgramData\Anaconda3\envs\gptac_venv\Lib\ssl.py", line 1075, in _create
    self.do_handshake()
  File "C:\ProgramData\Anaconda3\envs\gptac_venv\Lib\ssl.py", line 1346, in do_handshake
    self._sslobj.do_handshake()
urllib3.exceptions.ProtocolError: ('Connection aborted.', ConnectionResetError(10054, '远程主机强迫关闭了一个现有的连接。', None, 10054, None))

During handling of the above exception, another exception occurred:

Traceback (most recent call last):
  File "C:\Users\Tomoyo\Downloads\chatgpt_academic-master\crazy_functions\crazy_utils.py", line 186, in _req_gpt
    gpt_say = predict_no_ui_long_connection(
              ^^^^^^^^^^^^^^^^^^^^^^^^^^^^^^
  File "C:\Users\Tomoyo\Downloads\chatgpt_academic-master\request_llm\bridge_chatgpt.py", line 63, in predict_no_ui_long_connection
    response = requests.post(API_URL, headers=headers, proxies=proxies,
               ^^^^^^^^^^^^^^^^^^^^^^^^^^^^^^^^^^^^^^^^^^^^^^^^^^^^^^^^
  File "C:\ProgramData\Anaconda3\envs\gptac_venv\Lib\site-packages\requests\api.py", line 115, in post
    return request("post", url, data=data, json=json, **kwargs)
           ^^^^^^^^^^^^^^^^^^^^^^^^^^^^^^^^^^^^^^^^^^^^^^^^^^^^
  File "C:\ProgramData\Anaconda3\envs\gptac_venv\Lib\site-packages\requests\api.py", line 59, in request
    return session.request(method=method, url=url, **kwargs)
           ^^^^^^^^^^^^^^^^^^^^^^^^^^^^^^^^^^^^^^^^^^^^^^^^^
  File "C:\ProgramData\Anaconda3\envs\gptac_venv\Lib\site-packages\requests\sessions.py", line 587, in request
    resp = self.send(prep, **send_kwargs)
           ^^^^^^^^^^^^^^^^^^^^^^^^^^^^^^
  File "C:\ProgramData\Anaconda3\envs\gptac_venv\Lib\site-packages\requests\sessions.py", line 701, in send
    r = adapter.send(request, **kwargs)
        ^^^^^^^^^^^^^^^^^^^^^^^^^^^^^^^
  File "C:\ProgramData\Anaconda3\envs\gptac_venv\Lib\site-packages\requests\adapters.py", line 547, in send
    raise ConnectionError(err, request=request)
requests.exceptions.ConnectionError: ('Connection aborted.', ConnectionResetError(10054, '远程主机强迫关闭了一个现有的连接。', None, 10054, None))
```



## [14/22] 请对下面的程序文件做一个概述: C:\Users\Tomoyo\Desktop\lxh\mapper\RoleMapper.xml

[Local Message] 警告，线程14在执行过程中遭遇问题, Traceback：

```
Traceback (most recent call last):
  File "C:\Users\Tomoyo\Downloads\chatgpt_academic-master\crazy_functions\crazy_utils.py", line 186, in _req_gpt
    gpt_say = predict_no_ui_long_connection(
              ^^^^^^^^^^^^^^^^^^^^^^^^^^^^^^
  File "C:\Users\Tomoyo\Downloads\chatgpt_academic-master\request_llm\bridge_chatgpt.py", line 85, in predict_no_ui_long_connection
    raise RuntimeError("OpenAI拒绝了请求：" + error_msg)
RuntimeError: OpenAI拒绝了请求：{    "error": {        "message": "Rate limit reached for default-gpt-3.5-turbo in organization org-rPNvSW70tLGxHIiUZV8ERzxN on requests per min. Limit: 3 / min. Please try again in 20s. Contact us through our help center at help.openai.com if you continue to have issues. Please add a payment method to your account to increase your rate limit. Visit https://platform.openai.com/account/billing to add a payment method.",        "type": "requests",        "param": null,        "code": null    }}
```

[Local Message] 警告，线程14在执行过程中遭遇问题, Traceback：

```
Traceback (most recent call last):
  File "C:\Users\Tomoyo\Downloads\chatgpt_academic-master\crazy_functions\crazy_utils.py", line 186, in _req_gpt
    gpt_say = predict_no_ui_long_connection(
              ^^^^^^^^^^^^^^^^^^^^^^^^^^^^^^
  File "C:\Users\Tomoyo\Downloads\chatgpt_academic-master\request_llm\bridge_chatgpt.py", line 85, in predict_no_ui_long_connection
    raise RuntimeError("OpenAI拒绝了请求：" + error_msg)
RuntimeError: OpenAI拒绝了请求：{    "error": {        "message": "Rate limit reached for default-gpt-3.5-turbo in organization org-rPNvSW70tLGxHIiUZV8ERzxN on requests per min. Limit: 3 / min. Please try again in 20s. Contact us through our help center at help.openai.com if you continue to have issues. Please add a payment method to your account to increase your rate limit. Visit https://platform.openai.com/account/billing to add a payment method.",        "type": "requests",        "param": null,        "code": null    }}
```

[Local Message] 警告，线程14在执行过程中遭遇问题, Traceback：

```
Traceback (most recent call last):
  File "C:\Users\Tomoyo\Downloads\chatgpt_academic-master\crazy_functions\crazy_utils.py", line 186, in _req_gpt
    gpt_say = predict_no_ui_long_connection(
              ^^^^^^^^^^^^^^^^^^^^^^^^^^^^^^
  File "C:\Users\Tomoyo\Downloads\chatgpt_academic-master\request_llm\bridge_chatgpt.py", line 85, in predict_no_ui_long_connection
    raise RuntimeError("OpenAI拒绝了请求：" + error_msg)
RuntimeError: OpenAI拒绝了请求：{    "error": {        "message": "Rate limit reached for default-gpt-3.5-turbo in organization org-rPNvSW70tLGxHIiUZV8ERzxN on requests per min. Limit: 3 / min. Please try again in 20s. Contact us through our help center at help.openai.com if you continue to have issues. Please add a payment method to your account to increase your rate limit. Visit https://platform.openai.com/account/billing to add a payment method.",        "type": "requests",        "param": null,        "code": null    }}
```



## [15/22] 请对下面的程序文件做一个概述: C:\Users\Tomoyo\Desktop\lxh\mapper\SelectedcourseMapper.xml

该文件为MyBatis Mapper映射文件，命名为SelectedcourseMapper.xml，其中定义了一个命名空间为com.system.mapper.SelectedcourseMapper的Mapper接口。在文件中定义了多个SQL语句，包括select、delete、insert、update和count等操作，它们的具体实现是通过调用对应的SQL语句来实现的。此外，还定义了一些常量和参数，如BaseResultMap和Base_Column_List等。文件中的元素包括：resultMap、sql、select、delete、insert、parameterType、if、set、foreach、choose、when、otherwise等。

## [16/22] 请对下面的程序文件做一个概述: C:\Users\Tomoyo\Desktop\lxh\mapper\StudentMapper.xml

[Local Message] 警告，线程16在执行过程中遭遇问题, Traceback：

```
Traceback (most recent call last):
  File "C:\Users\Tomoyo\Downloads\chatgpt_academic-master\crazy_functions\crazy_utils.py", line 186, in _req_gpt
    gpt_say = predict_no_ui_long_connection(
              ^^^^^^^^^^^^^^^^^^^^^^^^^^^^^^
  File "C:\Users\Tomoyo\Downloads\chatgpt_academic-master\request_llm\bridge_chatgpt.py", line 85, in predict_no_ui_long_connection
    raise RuntimeError("OpenAI拒绝了请求：" + error_msg)
RuntimeError: OpenAI拒绝了请求：{    "error": {        "message": "Rate limit reached for default-gpt-3.5-turbo in organization org-rPNvSW70tLGxHIiUZV8ERzxN on requests per min. Limit: 3 / min. Please try again in 20s. Contact us through our help center at help.openai.com if you continue to have issues. Please add a payment method to your account to increase your rate limit. Visit https://platform.openai.com/account/billing to add a payment method.",        "type": "requests",        "param": null,        "code": null    }}
```

[Local Message] 警告，线程16在执行过程中遭遇问题, Traceback：

```
Traceback (most recent call last):
  File "C:\Users\Tomoyo\Downloads\chatgpt_academic-master\crazy_functions\crazy_utils.py", line 186, in _req_gpt
    gpt_say = predict_no_ui_long_connection(
              ^^^^^^^^^^^^^^^^^^^^^^^^^^^^^^
  File "C:\Users\Tomoyo\Downloads\chatgpt_academic-master\request_llm\bridge_chatgpt.py", line 85, in predict_no_ui_long_connection
    raise RuntimeError("OpenAI拒绝了请求：" + error_msg)
RuntimeError: OpenAI拒绝了请求：{    "error": {        "message": "Rate limit reached for default-gpt-3.5-turbo in organization org-rPNvSW70tLGxHIiUZV8ERzxN on requests per min. Limit: 3 / min. Please try again in 20s. Contact us through our help center at help.openai.com if you continue to have issues. Please add a payment method to your account to increase your rate limit. Visit https://platform.openai.com/account/billing to add a payment method.",        "type": "requests",        "param": null,        "code": null    }}
```

[Local Message] 警告，线程16在执行过程中遭遇问题, Traceback：

```
Traceback (most recent call last):
  File "C:\Users\Tomoyo\Downloads\chatgpt_academic-master\crazy_functions\crazy_utils.py", line 186, in _req_gpt
    gpt_say = predict_no_ui_long_connection(
              ^^^^^^^^^^^^^^^^^^^^^^^^^^^^^^
  File "C:\Users\Tomoyo\Downloads\chatgpt_academic-master\request_llm\bridge_chatgpt.py", line 85, in predict_no_ui_long_connection
    raise RuntimeError("OpenAI拒绝了请求：" + error_msg)
RuntimeError: OpenAI拒绝了请求：{    "error": {        "message": "Rate limit reached for default-gpt-3.5-turbo in organization org-rPNvSW70tLGxHIiUZV8ERzxN on requests per min. Limit: 3 / min. Please try again in 20s. Contact us through our help center at help.openai.com if you continue to have issues. Please add a payment method to your account to increase your rate limit. Visit https://platform.openai.com/account/billing to add a payment method.",        "type": "requests",        "param": null,        "code": null    }}
```



## [17/22] 请对下面的程序文件做一个概述: C:\Users\Tomoyo\Desktop\lxh\mapper\StudentMapperCustom.xml

[Local Message] 警告，线程17在执行过程中遭遇问题, Traceback：

```
Traceback (most recent call last):
  File "C:\Users\Tomoyo\Downloads\chatgpt_academic-master\crazy_functions\crazy_utils.py", line 186, in _req_gpt
    gpt_say = predict_no_ui_long_connection(
              ^^^^^^^^^^^^^^^^^^^^^^^^^^^^^^
  File "C:\Users\Tomoyo\Downloads\chatgpt_academic-master\request_llm\bridge_chatgpt.py", line 85, in predict_no_ui_long_connection
    raise RuntimeError("OpenAI拒绝了请求：" + error_msg)
RuntimeError: OpenAI拒绝了请求：{    "error": {        "message": "Rate limit reached for default-gpt-3.5-turbo in organization org-rPNvSW70tLGxHIiUZV8ERzxN on requests per min. Limit: 3 / min. Please try again in 20s. Contact us through our help center at help.openai.com if you continue to have issues. Please add a payment method to your account to increase your rate limit. Visit https://platform.openai.com/account/billing to add a payment method.",        "type": "requests",        "param": null,        "code": null    }}
```

[Local Message] 警告，线程17在执行过程中遭遇问题, Traceback：

```
Traceback (most recent call last):
  File "C:\Users\Tomoyo\Downloads\chatgpt_academic-master\crazy_functions\crazy_utils.py", line 186, in _req_gpt
    gpt_say = predict_no_ui_long_connection(
              ^^^^^^^^^^^^^^^^^^^^^^^^^^^^^^
  File "C:\Users\Tomoyo\Downloads\chatgpt_academic-master\request_llm\bridge_chatgpt.py", line 85, in predict_no_ui_long_connection
    raise RuntimeError("OpenAI拒绝了请求：" + error_msg)
RuntimeError: OpenAI拒绝了请求：{    "error": {        "message": "Rate limit reached for default-gpt-3.5-turbo in organization org-rPNvSW70tLGxHIiUZV8ERzxN on requests per min. Limit: 3 / min. Please try again in 20s. Contact us through our help center at help.openai.com if you continue to have issues. Please add a payment method to your account to increase your rate limit. Visit https://platform.openai.com/account/billing to add a payment method.",        "type": "requests",        "param": null,        "code": null    }}
```

[Local Message] 警告，线程17在执行过程中遭遇问题, Traceback：

```
Traceback (most recent call last):
  File "C:\Users\Tomoyo\Downloads\chatgpt_academic-master\crazy_functions\crazy_utils.py", line 186, in _req_gpt
    gpt_say = predict_no_ui_long_connection(
              ^^^^^^^^^^^^^^^^^^^^^^^^^^^^^^
  File "C:\Users\Tomoyo\Downloads\chatgpt_academic-master\request_llm\bridge_chatgpt.py", line 85, in predict_no_ui_long_connection
    raise RuntimeError("OpenAI拒绝了请求：" + error_msg)
RuntimeError: OpenAI拒绝了请求：{    "error": {        "message": "Rate limit reached for default-gpt-3.5-turbo in organization org-rPNvSW70tLGxHIiUZV8ERzxN on requests per min. Limit: 3 / min. Please try again in 20s. Contact us through our help center at help.openai.com if you continue to have issues. Please add a payment method to your account to increase your rate limit. Visit https://platform.openai.com/account/billing to add a payment method.",        "type": "requests",        "param": null,        "code": null    }}
```



## [18/22] 请对下面的程序文件做一个概述: C:\Users\Tomoyo\Desktop\lxh\mapper\TeacherMapper.xml

该代码文件是一个MyBatis的mapper文件，用于映射与教师相关的数据库表。它主要包含了教师实体类的属性与数据库表字段的映射关系，并定义了一些SQL查询语句。例如，它指定了如何进行基于Example的查询(selectByExample)、基于主键的查询(selectByPrimaryKey)、基于Example的更新(updateByExample)、基于主键的更新(updateByPrimaryKey)、基于Example的删除(deleteByExample)以及基于主键的删除(deleteByPrimaryKey)，以及SQL语句的参数和返回值。

## [19/22] 请对下面的程序文件做一个概述: C:\Users\Tomoyo\Desktop\lxh\mapper\TeacherMapperCustom.xml

[Local Message] 警告，线程19在执行过程中遭遇问题, Traceback：

```
Traceback (most recent call last):
  File "C:\Users\Tomoyo\Downloads\chatgpt_academic-master\crazy_functions\crazy_utils.py", line 186, in _req_gpt
    gpt_say = predict_no_ui_long_connection(
              ^^^^^^^^^^^^^^^^^^^^^^^^^^^^^^
  File "C:\Users\Tomoyo\Downloads\chatgpt_academic-master\request_llm\bridge_chatgpt.py", line 85, in predict_no_ui_long_connection
    raise RuntimeError("OpenAI拒绝了请求：" + error_msg)
RuntimeError: OpenAI拒绝了请求：{    "error": {        "message": "Rate limit reached for default-gpt-3.5-turbo in organization org-rPNvSW70tLGxHIiUZV8ERzxN on requests per min. Limit: 3 / min. Please try again in 20s. Contact us through our help center at help.openai.com if you continue to have issues. Please add a payment method to your account to increase your rate limit. Visit https://platform.openai.com/account/billing to add a payment method.",        "type": "requests",        "param": null,        "code": null    }}
```

[Local Message] 警告，线程19在执行过程中遭遇问题, Traceback：

```
Traceback (most recent call last):
  File "C:\Users\Tomoyo\Downloads\chatgpt_academic-master\crazy_functions\crazy_utils.py", line 186, in _req_gpt
    gpt_say = predict_no_ui_long_connection(
              ^^^^^^^^^^^^^^^^^^^^^^^^^^^^^^
  File "C:\Users\Tomoyo\Downloads\chatgpt_academic-master\request_llm\bridge_chatgpt.py", line 85, in predict_no_ui_long_connection
    raise RuntimeError("OpenAI拒绝了请求：" + error_msg)
RuntimeError: OpenAI拒绝了请求：{    "error": {        "message": "Rate limit reached for default-gpt-3.5-turbo in organization org-rPNvSW70tLGxHIiUZV8ERzxN on requests per min. Limit: 3 / min. Please try again in 20s. Contact us through our help center at help.openai.com if you continue to have issues. Please add a payment method to your account to increase your rate limit. Visit https://platform.openai.com/account/billing to add a payment method.",        "type": "requests",        "param": null,        "code": null    }}
```

[Local Message] 警告，线程19在执行过程中遭遇问题, Traceback：

```
Traceback (most recent call last):
  File "C:\Users\Tomoyo\Downloads\chatgpt_academic-master\crazy_functions\crazy_utils.py", line 186, in _req_gpt
    gpt_say = predict_no_ui_long_connection(
              ^^^^^^^^^^^^^^^^^^^^^^^^^^^^^^
  File "C:\Users\Tomoyo\Downloads\chatgpt_academic-master\request_llm\bridge_chatgpt.py", line 85, in predict_no_ui_long_connection
    raise RuntimeError("OpenAI拒绝了请求：" + error_msg)
RuntimeError: OpenAI拒绝了请求：{    "error": {        "message": "Rate limit reached for default-gpt-3.5-turbo in organization org-rPNvSW70tLGxHIiUZV8ERzxN on requests per min. Limit: 3 / min. Please try again in 20s. Contact us through our help center at help.openai.com if you continue to have issues. Please add a payment method to your account to increase your rate limit. Visit https://platform.openai.com/account/billing to add a payment method.",        "type": "requests",        "param": null,        "code": null    }}
```



## [20/22] 请对下面的程序文件做一个概述: C:\Users\Tomoyo\Desktop\lxh\mapper\UserloginMapper.xml

[Local Message] 警告，线程20在执行过程中遭遇问题, Traceback：

```
Traceback (most recent call last):
  File "C:\Users\Tomoyo\Downloads\chatgpt_academic-master\crazy_functions\crazy_utils.py", line 186, in _req_gpt
    gpt_say = predict_no_ui_long_connection(
              ^^^^^^^^^^^^^^^^^^^^^^^^^^^^^^
  File "C:\Users\Tomoyo\Downloads\chatgpt_academic-master\request_llm\bridge_chatgpt.py", line 85, in predict_no_ui_long_connection
    raise RuntimeError("OpenAI拒绝了请求：" + error_msg)
RuntimeError: OpenAI拒绝了请求：{    "error": {        "message": "Rate limit reached for default-gpt-3.5-turbo in organization org-rPNvSW70tLGxHIiUZV8ERzxN on requests per min. Limit: 3 / min. Please try again in 20s. Contact us through our help center at help.openai.com if you continue to have issues. Please add a payment method to your account to increase your rate limit. Visit https://platform.openai.com/account/billing to add a payment method.",        "type": "requests",        "param": null,        "code": null    }}
```

[Local Message] 警告，线程20在执行过程中遭遇问题, Traceback：

```
Traceback (most recent call last):
  File "C:\Users\Tomoyo\Downloads\chatgpt_academic-master\crazy_functions\crazy_utils.py", line 186, in _req_gpt
    gpt_say = predict_no_ui_long_connection(
              ^^^^^^^^^^^^^^^^^^^^^^^^^^^^^^
  File "C:\Users\Tomoyo\Downloads\chatgpt_academic-master\request_llm\bridge_chatgpt.py", line 85, in predict_no_ui_long_connection
    raise RuntimeError("OpenAI拒绝了请求：" + error_msg)
RuntimeError: OpenAI拒绝了请求：{    "error": {        "message": "Rate limit reached for default-gpt-3.5-turbo in organization org-rPNvSW70tLGxHIiUZV8ERzxN on requests per min. Limit: 3 / min. Please try again in 20s. Contact us through our help center at help.openai.com if you continue to have issues. Please add a payment method to your account to increase your rate limit. Visit https://platform.openai.com/account/billing to add a payment method.",        "type": "requests",        "param": null,        "code": null    }}
```

[Local Message] 警告，线程20在执行过程中遭遇问题, Traceback：

```
Traceback (most recent call last):
  File "C:\Users\Tomoyo\Downloads\chatgpt_academic-master\crazy_functions\crazy_utils.py", line 186, in _req_gpt
    gpt_say = predict_no_ui_long_connection(
              ^^^^^^^^^^^^^^^^^^^^^^^^^^^^^^
  File "C:\Users\Tomoyo\Downloads\chatgpt_academic-master\request_llm\bridge_chatgpt.py", line 85, in predict_no_ui_long_connection
    raise RuntimeError("OpenAI拒绝了请求：" + error_msg)
RuntimeError: OpenAI拒绝了请求：{    "error": {        "message": "Rate limit reached for default-gpt-3.5-turbo in organization org-rPNvSW70tLGxHIiUZV8ERzxN on requests per min. Limit: 3 / min. Please try again in 20s. Contact us through our help center at help.openai.com if you continue to have issues. Please add a payment method to your account to increase your rate limit. Visit https://platform.openai.com/account/billing to add a payment method.",        "type": "requests",        "param": null,        "code": null    }}
```



## [21/22] 请对下面的程序文件做一个概述: C:\Users\Tomoyo\Desktop\lxh\mapper\UserloginMapperCustom.xml

[Local Message] 警告，线程21在执行过程中遭遇问题, Traceback：

```
Traceback (most recent call last):
  File "C:\Users\Tomoyo\Downloads\chatgpt_academic-master\crazy_functions\crazy_utils.py", line 186, in _req_gpt
    gpt_say = predict_no_ui_long_connection(
              ^^^^^^^^^^^^^^^^^^^^^^^^^^^^^^
  File "C:\Users\Tomoyo\Downloads\chatgpt_academic-master\request_llm\bridge_chatgpt.py", line 85, in predict_no_ui_long_connection
    raise RuntimeError("OpenAI拒绝了请求：" + error_msg)
RuntimeError: OpenAI拒绝了请求：{    "error": {        "message": "Rate limit reached for default-gpt-3.5-turbo in organization org-rPNvSW70tLGxHIiUZV8ERzxN on requests per min. Limit: 3 / min. Please try again in 20s. Contact us through our help center at help.openai.com if you continue to have issues. Please add a payment method to your account to increase your rate limit. Visit https://platform.openai.com/account/billing to add a payment method.",        "type": "requests",        "param": null,        "code": null    }}
```

[Local Message] 警告，线程21在执行过程中遭遇问题, Traceback：

```
Traceback (most recent call last):
  File "C:\Users\Tomoyo\Downloads\chatgpt_academic-master\crazy_functions\crazy_utils.py", line 186, in _req_gpt
    gpt_say = predict_no_ui_long_connection(
              ^^^^^^^^^^^^^^^^^^^^^^^^^^^^^^
  File "C:\Users\Tomoyo\Downloads\chatgpt_academic-master\request_llm\bridge_chatgpt.py", line 85, in predict_no_ui_long_connection
    raise RuntimeError("OpenAI拒绝了请求：" + error_msg)
RuntimeError: OpenAI拒绝了请求：{    "error": {        "message": "Rate limit reached for default-gpt-3.5-turbo in organization org-rPNvSW70tLGxHIiUZV8ERzxN on requests per min. Limit: 3 / min. Please try again in 20s. Contact us through our help center at help.openai.com if you continue to have issues. Please add a payment method to your account to increase your rate limit. Visit https://platform.openai.com/account/billing to add a payment method.",        "type": "requests",        "param": null,        "code": null    }}
```

[Local Message] 警告，线程21在执行过程中遭遇问题, Traceback：

```
Traceback (most recent call last):
  File "C:\Users\Tomoyo\Downloads\chatgpt_academic-master\crazy_functions\crazy_utils.py", line 186, in _req_gpt
    gpt_say = predict_no_ui_long_connection(
              ^^^^^^^^^^^^^^^^^^^^^^^^^^^^^^
  File "C:\Users\Tomoyo\Downloads\chatgpt_academic-master\request_llm\bridge_chatgpt.py", line 85, in predict_no_ui_long_connection
    raise RuntimeError("OpenAI拒绝了请求：" + error_msg)
RuntimeError: OpenAI拒绝了请求：{    "error": {        "message": "Rate limit reached for default-gpt-3.5-turbo in organization org-rPNvSW70tLGxHIiUZV8ERzxN on requests per min. Limit: 3 / min. Please try again in 20s. Contact us through our help center at help.openai.com if you continue to have issues. Please add a payment method to your account to increase your rate limit. Visit https://platform.openai.com/account/billing to add a payment method.",        "type": "requests",        "param": null,        "code": null    }}
```



