# chatGPT 分析报告
## 接下来请你逐文件分析下面的工程[0/14] 请对下面的程序文件做一个概述: C:\Users\Tomoyo\Desktop\lxh\service\CollegeService.java

[Local Message] 警告，线程0在执行过程中遭遇问题, Traceback：

```
Traceback (most recent call last):
  File "C:\Users\Tomoyo\Downloads\chatgpt_academic-master\crazy_functions\crazy_utils.py", line 186, in _req_gpt
    gpt_say = predict_no_ui_long_connection(
              ^^^^^^^^^^^^^^^^^^^^^^^^^^^^^^
  File "C:\Users\Tomoyo\Downloads\chatgpt_academic-master\request_llm\bridge_chatgpt.py", line 85, in predict_no_ui_long_connection
    raise RuntimeError("OpenAI拒绝了请求：" + error_msg)
RuntimeError: OpenAI拒绝了请求：{    "error": {        "message": "Rate limit reached for default-gpt-3.5-turbo in organization org-rPNvSW70tLGxHIiUZV8ERzxN on requests per min. Limit: 3 / min. Please try again in 20s. Contact us through our help center at help.openai.com if you continue to have issues. Please add a payment method to your account to increase your rate limit. Visit https://platform.openai.com/account/billing to add a payment method.",        "type": "requests",        "param": null,        "code": null    }}
```

[Local Message] 警告，线程0在执行过程中遭遇问题, Traceback：

```
Traceback (most recent call last):
  File "C:\Users\Tomoyo\Downloads\chatgpt_academic-master\crazy_functions\crazy_utils.py", line 186, in _req_gpt
    gpt_say = predict_no_ui_long_connection(
              ^^^^^^^^^^^^^^^^^^^^^^^^^^^^^^
  File "C:\Users\Tomoyo\Downloads\chatgpt_academic-master\request_llm\bridge_chatgpt.py", line 85, in predict_no_ui_long_connection
    raise RuntimeError("OpenAI拒绝了请求：" + error_msg)
RuntimeError: OpenAI拒绝了请求：{    "error": {        "message": "Rate limit reached for default-gpt-3.5-turbo in organization org-rPNvSW70tLGxHIiUZV8ERzxN on requests per min. Limit: 3 / min. Please try again in 20s. Contact us through our help center at help.openai.com if you continue to have issues. Please add a payment method to your account to increase your rate limit. Visit https://platform.openai.com/account/billing to add a payment method.",        "type": "requests",        "param": null,        "code": null    }}
```

[Local Message] 警告，线程0在执行过程中遭遇问题, Traceback：

```
Traceback (most recent call last):
  File "C:\Users\Tomoyo\Downloads\chatgpt_academic-master\crazy_functions\crazy_utils.py", line 186, in _req_gpt
    gpt_say = predict_no_ui_long_connection(
              ^^^^^^^^^^^^^^^^^^^^^^^^^^^^^^
  File "C:\Users\Tomoyo\Downloads\chatgpt_academic-master\request_llm\bridge_chatgpt.py", line 85, in predict_no_ui_long_connection
    raise RuntimeError("OpenAI拒绝了请求：" + error_msg)
RuntimeError: OpenAI拒绝了请求：{    "error": {        "message": "Rate limit reached for default-gpt-3.5-turbo in organization org-rPNvSW70tLGxHIiUZV8ERzxN on requests per min. Limit: 3 / min. Please try again in 20s. Contact us through our help center at help.openai.com if you continue to have issues. Please add a payment method to your account to increase your rate limit. Visit https://platform.openai.com/account/billing to add a payment method.",        "type": "requests",        "param": null,        "code": null    }}
```



## [1/14] 请对下面的程序文件做一个概述: C:\Users\Tomoyo\Desktop\lxh\service\CourseService.java

该程序文件是一个接口文件，名为CourseService，属于com.system.service包。接口中定义了对课程信息进行增删改查的方法，包括根据id更新课程信息、根据id删除课程信息、获取分页查询课程信息、插入课程信息、获取课程总数、根据id查询、根据名字查询以及根据教师id查找课程。

## [2/14] 请对下面的程序文件做一个概述: C:\Users\Tomoyo\Desktop\lxh\service\RoleService.java

[Local Message] 警告，线程2在执行过程中遭遇问题, Traceback：

```
Traceback (most recent call last):
  File "C:\ProgramData\Anaconda3\envs\gptac_venv\Lib\site-packages\urllib3\connectionpool.py", line 703, in urlopen
    httplib_response = self._make_request(
                       ^^^^^^^^^^^^^^^^^^^
  File "C:\ProgramData\Anaconda3\envs\gptac_venv\Lib\site-packages\urllib3\connectionpool.py", line 386, in _make_request
    self._validate_conn(conn)
  File "C:\ProgramData\Anaconda3\envs\gptac_venv\Lib\site-packages\urllib3\connectionpool.py", line 1042, in _validate_conn
    conn.connect()
  File "C:\ProgramData\Anaconda3\envs\gptac_venv\Lib\site-packages\urllib3\connection.py", line 419, in connect
    self.sock = ssl_wrap_socket(
                ^^^^^^^^^^^^^^^^
  File "C:\ProgramData\Anaconda3\envs\gptac_venv\Lib\site-packages\urllib3\util\ssl_.py", line 449, in ssl_wrap_socket
    ssl_sock = _ssl_wrap_socket_impl(
               ^^^^^^^^^^^^^^^^^^^^^^
  File "C:\ProgramData\Anaconda3\envs\gptac_venv\Lib\site-packages\urllib3\util\ssl_.py", line 493, in _ssl_wrap_socket_impl
    return ssl_context.wrap_socket(sock, server_hostname=server_hostname)
           ^^^^^^^^^^^^^^^^^^^^^^^^^^^^^^^^^^^^^^^^^^^^^^^^^^^^^^^^^^^^^^
  File "C:\ProgramData\Anaconda3\envs\gptac_venv\Lib\ssl.py", line 517, in wrap_socket
    return self.sslsocket_class._create(
           ^^^^^^^^^^^^^^^^^^^^^^^^^^^^^
  File "C:\ProgramData\Anaconda3\envs\gptac_venv\Lib\ssl.py", line 1075, in _create
    self.do_handshake()
  File "C:\ProgramData\Anaconda3\envs\gptac_venv\Lib\ssl.py", line 1346, in do_handshake
    self._sslobj.do_handshake()
ssl.SSLEOFError: [SSL: UNEXPECTED_EOF_WHILE_READING] EOF occurred in violation of protocol (_ssl.c:1002)

During handling of the above exception, another exception occurred:

Traceback (most recent call last):
  File "C:\ProgramData\Anaconda3\envs\gptac_venv\Lib\site-packages\requests\adapters.py", line 489, in send
    resp = conn.urlopen(
           ^^^^^^^^^^^^^
  File "C:\ProgramData\Anaconda3\envs\gptac_venv\Lib\site-packages\urllib3\connectionpool.py", line 787, in urlopen
    retries = retries.increment(
              ^^^^^^^^^^^^^^^^^^
  File "C:\ProgramData\Anaconda3\envs\gptac_venv\Lib\site-packages\urllib3\util\retry.py", line 592, in increment
    raise MaxRetryError(_pool, url, error or ResponseError(cause))
urllib3.exceptions.MaxRetryError: SOCKSHTTPSConnectionPool(host='api.openai.com', port=443): Max retries exceeded with url: /v1/chat/completions (Caused by SSLError(SSLEOFError(8, '[SSL: UNEXPECTED_EOF_WHILE_READING] EOF occurred in violation of protocol (_ssl.c:1002)')))

During handling of the above exception, another exception occurred:

Traceback (most recent call last):
  File "C:\Users\Tomoyo\Downloads\chatgpt_academic-master\crazy_functions\crazy_utils.py", line 186, in _req_gpt
    gpt_say = predict_no_ui_long_connection(
              ^^^^^^^^^^^^^^^^^^^^^^^^^^^^^^
  File "C:\Users\Tomoyo\Downloads\chatgpt_academic-master\request_llm\bridge_chatgpt.py", line 63, in predict_no_ui_long_connection
    response = requests.post(API_URL, headers=headers, proxies=proxies,
               ^^^^^^^^^^^^^^^^^^^^^^^^^^^^^^^^^^^^^^^^^^^^^^^^^^^^^^^^
  File "C:\ProgramData\Anaconda3\envs\gptac_venv\Lib\site-packages\requests\api.py", line 115, in post
    return request("post", url, data=data, json=json, **kwargs)
           ^^^^^^^^^^^^^^^^^^^^^^^^^^^^^^^^^^^^^^^^^^^^^^^^^^^^
  File "C:\ProgramData\Anaconda3\envs\gptac_venv\Lib\site-packages\requests\api.py", line 59, in request
    return session.request(method=method, url=url, **kwargs)
           ^^^^^^^^^^^^^^^^^^^^^^^^^^^^^^^^^^^^^^^^^^^^^^^^^
  File "C:\ProgramData\Anaconda3\envs\gptac_venv\Lib\site-packages\requests\sessions.py", line 587, in request
    resp = self.send(prep, **send_kwargs)
           ^^^^^^^^^^^^^^^^^^^^^^^^^^^^^^
  File "C:\ProgramData\Anaconda3\envs\gptac_venv\Lib\site-packages\requests\sessions.py", line 701, in send
    r = adapter.send(request, **kwargs)
        ^^^^^^^^^^^^^^^^^^^^^^^^^^^^^^^
  File "C:\ProgramData\Anaconda3\envs\gptac_venv\Lib\site-packages\requests\adapters.py", line 563, in send
    raise SSLError(e, request=request)
requests.exceptions.SSLError: SOCKSHTTPSConnectionPool(host='api.openai.com', port=443): Max retries exceeded with url: /v1/chat/completions (Caused by SSLError(SSLEOFError(8, '[SSL: UNEXPECTED_EOF_WHILE_READING] EOF occurred in violation of protocol (_ssl.c:1002)')))
```

[Local Message] 警告，线程2在执行过程中遭遇问题, Traceback：

```
Traceback (most recent call last):
  File "C:\Users\Tomoyo\Downloads\chatgpt_academic-master\crazy_functions\crazy_utils.py", line 186, in _req_gpt
    gpt_say = predict_no_ui_long_connection(
              ^^^^^^^^^^^^^^^^^^^^^^^^^^^^^^
  File "C:\Users\Tomoyo\Downloads\chatgpt_academic-master\request_llm\bridge_chatgpt.py", line 85, in predict_no_ui_long_connection
    raise RuntimeError("OpenAI拒绝了请求：" + error_msg)
RuntimeError: OpenAI拒绝了请求：{    "error": {        "message": "Rate limit reached for default-gpt-3.5-turbo in organization org-rPNvSW70tLGxHIiUZV8ERzxN on requests per min. Limit: 3 / min. Please try again in 20s. Contact us through our help center at help.openai.com if you continue to have issues. Please add a payment method to your account to increase your rate limit. Visit https://platform.openai.com/account/billing to add a payment method.",        "type": "requests",        "param": null,        "code": null    }}
```

[Local Message] 警告，线程2在执行过程中遭遇问题, Traceback：

```
Traceback (most recent call last):
  File "C:\Users\Tomoyo\Downloads\chatgpt_academic-master\crazy_functions\crazy_utils.py", line 186, in _req_gpt
    gpt_say = predict_no_ui_long_connection(
              ^^^^^^^^^^^^^^^^^^^^^^^^^^^^^^
  File "C:\Users\Tomoyo\Downloads\chatgpt_academic-master\request_llm\bridge_chatgpt.py", line 85, in predict_no_ui_long_connection
    raise RuntimeError("OpenAI拒绝了请求：" + error_msg)
RuntimeError: OpenAI拒绝了请求：{    "error": {        "message": "Rate limit reached for default-gpt-3.5-turbo in organization org-rPNvSW70tLGxHIiUZV8ERzxN on requests per min. Limit: 3 / min. Please try again in 20s. Contact us through our help center at help.openai.com if you continue to have issues. Please add a payment method to your account to increase your rate limit. Visit https://platform.openai.com/account/billing to add a payment method.",        "type": "requests",        "param": null,        "code": null    }}
```



## [3/14] 请对下面的程序文件做一个概述: C:\Users\Tomoyo\Desktop\lxh\service\SelectedCourseService.java

[Local Message] 警告，线程3在执行过程中遭遇问题, Traceback：

```
Traceback (most recent call last):
  File "C:\Users\Tomoyo\Downloads\chatgpt_academic-master\crazy_functions\crazy_utils.py", line 186, in _req_gpt
    gpt_say = predict_no_ui_long_connection(
              ^^^^^^^^^^^^^^^^^^^^^^^^^^^^^^
  File "C:\Users\Tomoyo\Downloads\chatgpt_academic-master\request_llm\bridge_chatgpt.py", line 85, in predict_no_ui_long_connection
    raise RuntimeError("OpenAI拒绝了请求：" + error_msg)
RuntimeError: OpenAI拒绝了请求：{    "error": {        "message": "Rate limit reached for default-gpt-3.5-turbo in organization org-rPNvSW70tLGxHIiUZV8ERzxN on requests per min. Limit: 3 / min. Please try again in 20s. Contact us through our help center at help.openai.com if you continue to have issues. Please add a payment method to your account to increase your rate limit. Visit https://platform.openai.com/account/billing to add a payment method.",        "type": "requests",        "param": null,        "code": null    }}
```

[Local Message] 警告，线程3在执行过程中遭遇问题, Traceback：

```
Traceback (most recent call last):
  File "C:\Users\Tomoyo\Downloads\chatgpt_academic-master\crazy_functions\crazy_utils.py", line 186, in _req_gpt
    gpt_say = predict_no_ui_long_connection(
              ^^^^^^^^^^^^^^^^^^^^^^^^^^^^^^
  File "C:\Users\Tomoyo\Downloads\chatgpt_academic-master\request_llm\bridge_chatgpt.py", line 85, in predict_no_ui_long_connection
    raise RuntimeError("OpenAI拒绝了请求：" + error_msg)
RuntimeError: OpenAI拒绝了请求：{    "error": {        "message": "Rate limit reached for default-gpt-3.5-turbo in organization org-rPNvSW70tLGxHIiUZV8ERzxN on requests per min. Limit: 3 / min. Please try again in 20s. Contact us through our help center at help.openai.com if you continue to have issues. Please add a payment method to your account to increase your rate limit. Visit https://platform.openai.com/account/billing to add a payment method.",        "type": "requests",        "param": null,        "code": null    }}
```

[Local Message] 警告，线程3在执行过程中遭遇问题, Traceback：

```
Traceback (most recent call last):
  File "C:\Users\Tomoyo\Downloads\chatgpt_academic-master\crazy_functions\crazy_utils.py", line 186, in _req_gpt
    gpt_say = predict_no_ui_long_connection(
              ^^^^^^^^^^^^^^^^^^^^^^^^^^^^^^
  File "C:\Users\Tomoyo\Downloads\chatgpt_academic-master\request_llm\bridge_chatgpt.py", line 85, in predict_no_ui_long_connection
    raise RuntimeError("OpenAI拒绝了请求：" + error_msg)
RuntimeError: OpenAI拒绝了请求：{    "error": {        "message": "Rate limit reached for default-gpt-3.5-turbo in organization org-rPNvSW70tLGxHIiUZV8ERzxN on requests per min. Limit: 3 / min. Please try again in 20s. Contact us through our help center at help.openai.com if you continue to have issues. Please add a payment method to your account to increase your rate limit. Visit https://platform.openai.com/account/billing to add a payment method.",        "type": "requests",        "param": null,        "code": null    }}
```



## [4/14] 请对下面的程序文件做一个概述: C:\Users\Tomoyo\Desktop\lxh\service\StudentService.java

[Local Message] 警告，线程4在执行过程中遭遇问题, Traceback：

```
Traceback (most recent call last):
  File "C:\Users\Tomoyo\Downloads\chatgpt_academic-master\crazy_functions\crazy_utils.py", line 186, in _req_gpt
    gpt_say = predict_no_ui_long_connection(
              ^^^^^^^^^^^^^^^^^^^^^^^^^^^^^^
  File "C:\Users\Tomoyo\Downloads\chatgpt_academic-master\request_llm\bridge_chatgpt.py", line 85, in predict_no_ui_long_connection
    raise RuntimeError("OpenAI拒绝了请求：" + error_msg)
RuntimeError: OpenAI拒绝了请求：{    "error": {        "message": "Rate limit reached for default-gpt-3.5-turbo in organization org-rPNvSW70tLGxHIiUZV8ERzxN on requests per min. Limit: 3 / min. Please try again in 20s. Contact us through our help center at help.openai.com if you continue to have issues. Please add a payment method to your account to increase your rate limit. Visit https://platform.openai.com/account/billing to add a payment method.",        "type": "requests",        "param": null,        "code": null    }}
```

[Local Message] 警告，线程4在执行过程中遭遇问题, Traceback：

```
Traceback (most recent call last):
  File "C:\Users\Tomoyo\Downloads\chatgpt_academic-master\crazy_functions\crazy_utils.py", line 186, in _req_gpt
    gpt_say = predict_no_ui_long_connection(
              ^^^^^^^^^^^^^^^^^^^^^^^^^^^^^^
  File "C:\Users\Tomoyo\Downloads\chatgpt_academic-master\request_llm\bridge_chatgpt.py", line 85, in predict_no_ui_long_connection
    raise RuntimeError("OpenAI拒绝了请求：" + error_msg)
RuntimeError: OpenAI拒绝了请求：{    "error": {        "message": "Rate limit reached for default-gpt-3.5-turbo in organization org-rPNvSW70tLGxHIiUZV8ERzxN on requests per min. Limit: 3 / min. Please try again in 20s. Contact us through our help center at help.openai.com if you continue to have issues. Please add a payment method to your account to increase your rate limit. Visit https://platform.openai.com/account/billing to add a payment method.",        "type": "requests",        "param": null,        "code": null    }}
```

[Local Message] 警告，线程4在执行过程中遭遇问题, Traceback：

```
Traceback (most recent call last):
  File "C:\Users\Tomoyo\Downloads\chatgpt_academic-master\crazy_functions\crazy_utils.py", line 186, in _req_gpt
    gpt_say = predict_no_ui_long_connection(
              ^^^^^^^^^^^^^^^^^^^^^^^^^^^^^^
  File "C:\Users\Tomoyo\Downloads\chatgpt_academic-master\request_llm\bridge_chatgpt.py", line 85, in predict_no_ui_long_connection
    raise RuntimeError("OpenAI拒绝了请求：" + error_msg)
RuntimeError: OpenAI拒绝了请求：{    "error": {        "message": "Rate limit reached for default-gpt-3.5-turbo in organization org-rPNvSW70tLGxHIiUZV8ERzxN on requests per min. Limit: 3 / min. Please try again in 20s. Contact us through our help center at help.openai.com if you continue to have issues. Please add a payment method to your account to increase your rate limit. Visit https://platform.openai.com/account/billing to add a payment method.",        "type": "requests",        "param": null,        "code": null    }}
```



## [5/14] 请对下面的程序文件做一个概述: C:\Users\Tomoyo\Desktop\lxh\service\TeacherService.java

[Local Message] 警告，线程5在执行过程中遭遇问题, Traceback：

```
Traceback (most recent call last):
  File "C:\Users\Tomoyo\Downloads\chatgpt_academic-master\crazy_functions\crazy_utils.py", line 186, in _req_gpt
    gpt_say = predict_no_ui_long_connection(
              ^^^^^^^^^^^^^^^^^^^^^^^^^^^^^^
  File "C:\Users\Tomoyo\Downloads\chatgpt_academic-master\request_llm\bridge_chatgpt.py", line 85, in predict_no_ui_long_connection
    raise RuntimeError("OpenAI拒绝了请求：" + error_msg)
RuntimeError: OpenAI拒绝了请求：{    "error": {        "message": "Rate limit reached for default-gpt-3.5-turbo in organization org-rPNvSW70tLGxHIiUZV8ERzxN on requests per min. Limit: 3 / min. Please try again in 20s. Contact us through our help center at help.openai.com if you continue to have issues. Please add a payment method to your account to increase your rate limit. Visit https://platform.openai.com/account/billing to add a payment method.",        "type": "requests",        "param": null,        "code": null    }}
```

[Local Message] 警告，线程5在执行过程中遭遇问题, Traceback：

```
Traceback (most recent call last):
  File "C:\Users\Tomoyo\Downloads\chatgpt_academic-master\crazy_functions\crazy_utils.py", line 186, in _req_gpt
    gpt_say = predict_no_ui_long_connection(
              ^^^^^^^^^^^^^^^^^^^^^^^^^^^^^^
  File "C:\Users\Tomoyo\Downloads\chatgpt_academic-master\request_llm\bridge_chatgpt.py", line 85, in predict_no_ui_long_connection
    raise RuntimeError("OpenAI拒绝了请求：" + error_msg)
RuntimeError: OpenAI拒绝了请求：{    "error": {        "message": "Rate limit reached for default-gpt-3.5-turbo in organization org-rPNvSW70tLGxHIiUZV8ERzxN on requests per min. Limit: 3 / min. Please try again in 20s. Contact us through our help center at help.openai.com if you continue to have issues. Please add a payment method to your account to increase your rate limit. Visit https://platform.openai.com/account/billing to add a payment method.",        "type": "requests",        "param": null,        "code": null    }}
```

[Local Message] 警告，线程5在执行过程中遭遇问题, Traceback：

```
Traceback (most recent call last):
  File "C:\Users\Tomoyo\Downloads\chatgpt_academic-master\crazy_functions\crazy_utils.py", line 186, in _req_gpt
    gpt_say = predict_no_ui_long_connection(
              ^^^^^^^^^^^^^^^^^^^^^^^^^^^^^^
  File "C:\Users\Tomoyo\Downloads\chatgpt_academic-master\request_llm\bridge_chatgpt.py", line 85, in predict_no_ui_long_connection
    raise RuntimeError("OpenAI拒绝了请求：" + error_msg)
RuntimeError: OpenAI拒绝了请求：{    "error": {        "message": "Rate limit reached for default-gpt-3.5-turbo in organization org-rPNvSW70tLGxHIiUZV8ERzxN on requests per min. Limit: 3 / min. Please try again in 20s. Contact us through our help center at help.openai.com if you continue to have issues. Please add a payment method to your account to increase your rate limit. Visit https://platform.openai.com/account/billing to add a payment method.",        "type": "requests",        "param": null,        "code": null    }}
```



## [6/14] 请对下面的程序文件做一个概述: C:\Users\Tomoyo\Desktop\lxh\service\UserloginService.java

[Local Message] 警告，线程6在执行过程中遭遇问题, Traceback：

```
Traceback (most recent call last):
  File "C:\Users\Tomoyo\Downloads\chatgpt_academic-master\crazy_functions\crazy_utils.py", line 186, in _req_gpt
    gpt_say = predict_no_ui_long_connection(
              ^^^^^^^^^^^^^^^^^^^^^^^^^^^^^^
  File "C:\Users\Tomoyo\Downloads\chatgpt_academic-master\request_llm\bridge_chatgpt.py", line 85, in predict_no_ui_long_connection
    raise RuntimeError("OpenAI拒绝了请求：" + error_msg)
RuntimeError: OpenAI拒绝了请求：{    "error": {        "message": "Rate limit reached for default-gpt-3.5-turbo in organization org-rPNvSW70tLGxHIiUZV8ERzxN on requests per min. Limit: 3 / min. Please try again in 20s. Contact us through our help center at help.openai.com if you continue to have issues. Please add a payment method to your account to increase your rate limit. Visit https://platform.openai.com/account/billing to add a payment method.",        "type": "requests",        "param": null,        "code": null    }}
```

[Local Message] 警告，线程6在执行过程中遭遇问题, Traceback：

```
Traceback (most recent call last):
  File "C:\Users\Tomoyo\Downloads\chatgpt_academic-master\crazy_functions\crazy_utils.py", line 186, in _req_gpt
    gpt_say = predict_no_ui_long_connection(
              ^^^^^^^^^^^^^^^^^^^^^^^^^^^^^^
  File "C:\Users\Tomoyo\Downloads\chatgpt_academic-master\request_llm\bridge_chatgpt.py", line 85, in predict_no_ui_long_connection
    raise RuntimeError("OpenAI拒绝了请求：" + error_msg)
RuntimeError: OpenAI拒绝了请求：{    "error": {        "message": "Rate limit reached for default-gpt-3.5-turbo in organization org-rPNvSW70tLGxHIiUZV8ERzxN on requests per min. Limit: 3 / min. Please try again in 20s. Contact us through our help center at help.openai.com if you continue to have issues. Please add a payment method to your account to increase your rate limit. Visit https://platform.openai.com/account/billing to add a payment method.",        "type": "requests",        "param": null,        "code": null    }}
```

[Local Message] 警告，线程6在执行过程中遭遇问题, Traceback：

```
Traceback (most recent call last):
  File "C:\Users\Tomoyo\Downloads\chatgpt_academic-master\crazy_functions\crazy_utils.py", line 186, in _req_gpt
    gpt_say = predict_no_ui_long_connection(
              ^^^^^^^^^^^^^^^^^^^^^^^^^^^^^^
  File "C:\Users\Tomoyo\Downloads\chatgpt_academic-master\request_llm\bridge_chatgpt.py", line 85, in predict_no_ui_long_connection
    raise RuntimeError("OpenAI拒绝了请求：" + error_msg)
RuntimeError: OpenAI拒绝了请求：{    "error": {        "message": "Rate limit reached for default-gpt-3.5-turbo in organization org-rPNvSW70tLGxHIiUZV8ERzxN on requests per min. Limit: 3 / min. Please try again in 20s. Contact us through our help center at help.openai.com if you continue to have issues. Please add a payment method to your account to increase your rate limit. Visit https://platform.openai.com/account/billing to add a payment method.",        "type": "requests",        "param": null,        "code": null    }}
```



## [7/14] 请对下面的程序文件做一个概述: C:\Users\Tomoyo\Desktop\lxh\service\impl\CollegeServiceImpl.java

[Local Message] 警告，线程7在执行过程中遭遇问题, Traceback：

```
Traceback (most recent call last):
  File "C:\Users\Tomoyo\Downloads\chatgpt_academic-master\crazy_functions\crazy_utils.py", line 186, in _req_gpt
    gpt_say = predict_no_ui_long_connection(
              ^^^^^^^^^^^^^^^^^^^^^^^^^^^^^^
  File "C:\Users\Tomoyo\Downloads\chatgpt_academic-master\request_llm\bridge_chatgpt.py", line 85, in predict_no_ui_long_connection
    raise RuntimeError("OpenAI拒绝了请求：" + error_msg)
RuntimeError: OpenAI拒绝了请求：{    "error": {        "message": "Rate limit reached for default-gpt-3.5-turbo in organization org-rPNvSW70tLGxHIiUZV8ERzxN on requests per min. Limit: 3 / min. Please try again in 20s. Contact us through our help center at help.openai.com if you continue to have issues. Please add a payment method to your account to increase your rate limit. Visit https://platform.openai.com/account/billing to add a payment method.",        "type": "requests",        "param": null,        "code": null    }}
```

[Local Message] 警告，线程7在执行过程中遭遇问题, Traceback：

```
Traceback (most recent call last):
  File "C:\Users\Tomoyo\Downloads\chatgpt_academic-master\crazy_functions\crazy_utils.py", line 186, in _req_gpt
    gpt_say = predict_no_ui_long_connection(
              ^^^^^^^^^^^^^^^^^^^^^^^^^^^^^^
  File "C:\Users\Tomoyo\Downloads\chatgpt_academic-master\request_llm\bridge_chatgpt.py", line 85, in predict_no_ui_long_connection
    raise RuntimeError("OpenAI拒绝了请求：" + error_msg)
RuntimeError: OpenAI拒绝了请求：{    "error": {        "message": "Rate limit reached for default-gpt-3.5-turbo in organization org-rPNvSW70tLGxHIiUZV8ERzxN on requests per min. Limit: 3 / min. Please try again in 20s. Contact us through our help center at help.openai.com if you continue to have issues. Please add a payment method to your account to increase your rate limit. Visit https://platform.openai.com/account/billing to add a payment method.",        "type": "requests",        "param": null,        "code": null    }}
```

[Local Message] 警告，线程7在执行过程中遭遇问题, Traceback：

```
Traceback (most recent call last):
  File "C:\Users\Tomoyo\Downloads\chatgpt_academic-master\crazy_functions\crazy_utils.py", line 186, in _req_gpt
    gpt_say = predict_no_ui_long_connection(
              ^^^^^^^^^^^^^^^^^^^^^^^^^^^^^^
  File "C:\Users\Tomoyo\Downloads\chatgpt_academic-master\request_llm\bridge_chatgpt.py", line 85, in predict_no_ui_long_connection
    raise RuntimeError("OpenAI拒绝了请求：" + error_msg)
RuntimeError: OpenAI拒绝了请求：{    "error": {        "message": "Rate limit reached for default-gpt-3.5-turbo in organization org-rPNvSW70tLGxHIiUZV8ERzxN on requests per min. Limit: 3 / min. Please try again in 20s. Contact us through our help center at help.openai.com if you continue to have issues. Please add a payment method to your account to increase your rate limit. Visit https://platform.openai.com/account/billing to add a payment method.",        "type": "requests",        "param": null,        "code": null    }}
```



## [8/14] 请对下面的程序文件做一个概述: C:\Users\Tomoyo\Desktop\lxh\service\impl\CourseServiceImpl.java

该文件是一个Java源代码文件，路径为service\impl\CourseServiceImpl.java。它实现了CourseService接口并包含了处理课程数据的方法，例如根据条件查询课程、按照分页查找课程、通过ID删除课程等。还有一些自定义的查询条件和类拷贝，以及一些该类所需的引用的其他类。整体上，该文件是一个服务实现类，为其他类提供课程数据服务。

## [9/14] 请对下面的程序文件做一个概述: C:\Users\Tomoyo\Desktop\lxh\service\impl\RoleServiceImpl.java

[Local Message] 警告，线程9在执行过程中遭遇问题, Traceback：

```
Traceback (most recent call last):
  File "C:\Users\Tomoyo\Downloads\chatgpt_academic-master\crazy_functions\crazy_utils.py", line 186, in _req_gpt
    gpt_say = predict_no_ui_long_connection(
              ^^^^^^^^^^^^^^^^^^^^^^^^^^^^^^
  File "C:\Users\Tomoyo\Downloads\chatgpt_academic-master\request_llm\bridge_chatgpt.py", line 85, in predict_no_ui_long_connection
    raise RuntimeError("OpenAI拒绝了请求：" + error_msg)
RuntimeError: OpenAI拒绝了请求：{    "error": {        "message": "Rate limit reached for default-gpt-3.5-turbo in organization org-rPNvSW70tLGxHIiUZV8ERzxN on requests per min. Limit: 3 / min. Please try again in 20s. Contact us through our help center at help.openai.com if you continue to have issues. Please add a payment method to your account to increase your rate limit. Visit https://platform.openai.com/account/billing to add a payment method.",        "type": "requests",        "param": null,        "code": null    }}
```

[Local Message] 警告，线程9在执行过程中遭遇问题, Traceback：

```
Traceback (most recent call last):
  File "C:\Users\Tomoyo\Downloads\chatgpt_academic-master\crazy_functions\crazy_utils.py", line 186, in _req_gpt
    gpt_say = predict_no_ui_long_connection(
              ^^^^^^^^^^^^^^^^^^^^^^^^^^^^^^
  File "C:\Users\Tomoyo\Downloads\chatgpt_academic-master\request_llm\bridge_chatgpt.py", line 85, in predict_no_ui_long_connection
    raise RuntimeError("OpenAI拒绝了请求：" + error_msg)
RuntimeError: OpenAI拒绝了请求：{    "error": {        "message": "Rate limit reached for default-gpt-3.5-turbo in organization org-rPNvSW70tLGxHIiUZV8ERzxN on requests per min. Limit: 3 / min. Please try again in 20s. Contact us through our help center at help.openai.com if you continue to have issues. Please add a payment method to your account to increase your rate limit. Visit https://platform.openai.com/account/billing to add a payment method.",        "type": "requests",        "param": null,        "code": null    }}
```

[Local Message] 警告，线程9在执行过程中遭遇问题, Traceback：

```
Traceback (most recent call last):
  File "C:\Users\Tomoyo\Downloads\chatgpt_academic-master\crazy_functions\crazy_utils.py", line 186, in _req_gpt
    gpt_say = predict_no_ui_long_connection(
              ^^^^^^^^^^^^^^^^^^^^^^^^^^^^^^
  File "C:\Users\Tomoyo\Downloads\chatgpt_academic-master\request_llm\bridge_chatgpt.py", line 85, in predict_no_ui_long_connection
    raise RuntimeError("OpenAI拒绝了请求：" + error_msg)
RuntimeError: OpenAI拒绝了请求：{    "error": {        "message": "Rate limit reached for default-gpt-3.5-turbo in organization org-rPNvSW70tLGxHIiUZV8ERzxN on requests per min. Limit: 3 / min. Please try again in 20s. Contact us through our help center at help.openai.com if you continue to have issues. Please add a payment method to your account to increase your rate limit. Visit https://platform.openai.com/account/billing to add a payment method.",        "type": "requests",        "param": null,        "code": null    }}
```



## [10/14] 请对下面的程序文件做一个概述: C:\Users\Tomoyo\Desktop\lxh\service\impl\SelectedCourseServiceImpl.java

[Local Message] 警告，线程10在执行过程中遭遇问题, Traceback：

```
Traceback (most recent call last):
  File "C:\Users\Tomoyo\Downloads\chatgpt_academic-master\crazy_functions\crazy_utils.py", line 186, in _req_gpt
    gpt_say = predict_no_ui_long_connection(
              ^^^^^^^^^^^^^^^^^^^^^^^^^^^^^^
  File "C:\Users\Tomoyo\Downloads\chatgpt_academic-master\request_llm\bridge_chatgpt.py", line 85, in predict_no_ui_long_connection
    raise RuntimeError("OpenAI拒绝了请求：" + error_msg)
RuntimeError: OpenAI拒绝了请求：{    "error": {        "message": "Rate limit reached for default-gpt-3.5-turbo in organization org-rPNvSW70tLGxHIiUZV8ERzxN on requests per min. Limit: 3 / min. Please try again in 20s. Contact us through our help center at help.openai.com if you continue to have issues. Please add a payment method to your account to increase your rate limit. Visit https://platform.openai.com/account/billing to add a payment method.",        "type": "requests",        "param": null,        "code": null    }}
```

[Local Message] 警告，线程10在执行过程中遭遇问题, Traceback：

```
Traceback (most recent call last):
  File "C:\Users\Tomoyo\Downloads\chatgpt_academic-master\crazy_functions\crazy_utils.py", line 186, in _req_gpt
    gpt_say = predict_no_ui_long_connection(
              ^^^^^^^^^^^^^^^^^^^^^^^^^^^^^^
  File "C:\Users\Tomoyo\Downloads\chatgpt_academic-master\request_llm\bridge_chatgpt.py", line 85, in predict_no_ui_long_connection
    raise RuntimeError("OpenAI拒绝了请求：" + error_msg)
RuntimeError: OpenAI拒绝了请求：{    "error": {        "message": "Rate limit reached for default-gpt-3.5-turbo in organization org-rPNvSW70tLGxHIiUZV8ERzxN on requests per min. Limit: 3 / min. Please try again in 20s. Contact us through our help center at help.openai.com if you continue to have issues. Please add a payment method to your account to increase your rate limit. Visit https://platform.openai.com/account/billing to add a payment method.",        "type": "requests",        "param": null,        "code": null    }}
```

[Local Message] 警告，线程10在执行过程中遭遇问题, Traceback：

```
Traceback (most recent call last):
  File "C:\Users\Tomoyo\Downloads\chatgpt_academic-master\crazy_functions\crazy_utils.py", line 186, in _req_gpt
    gpt_say = predict_no_ui_long_connection(
              ^^^^^^^^^^^^^^^^^^^^^^^^^^^^^^
  File "C:\Users\Tomoyo\Downloads\chatgpt_academic-master\request_llm\bridge_chatgpt.py", line 85, in predict_no_ui_long_connection
    raise RuntimeError("OpenAI拒绝了请求：" + error_msg)
RuntimeError: OpenAI拒绝了请求：{    "error": {        "message": "Rate limit reached for default-gpt-3.5-turbo in organization org-rPNvSW70tLGxHIiUZV8ERzxN on requests per min. Limit: 3 / min. Please try again in 20s. Contact us through our help center at help.openai.com if you continue to have issues. Please add a payment method to your account to increase your rate limit. Visit https://platform.openai.com/account/billing to add a payment method.",        "type": "requests",        "param": null,        "code": null    }}
```



## [11/14] 请对下面的程序文件做一个概述: C:\Users\Tomoyo\Desktop\lxh\service\impl\StudentServiceImpl.java

[Local Message] 警告，线程11在执行过程中遭遇问题, Traceback：

```
Traceback (most recent call last):
  File "C:\Users\Tomoyo\Downloads\chatgpt_academic-master\crazy_functions\crazy_utils.py", line 186, in _req_gpt
    gpt_say = predict_no_ui_long_connection(
              ^^^^^^^^^^^^^^^^^^^^^^^^^^^^^^
  File "C:\Users\Tomoyo\Downloads\chatgpt_academic-master\request_llm\bridge_chatgpt.py", line 85, in predict_no_ui_long_connection
    raise RuntimeError("OpenAI拒绝了请求：" + error_msg)
RuntimeError: OpenAI拒绝了请求：{    "error": {        "message": "Rate limit reached for default-gpt-3.5-turbo in organization org-rPNvSW70tLGxHIiUZV8ERzxN on requests per min. Limit: 3 / min. Please try again in 20s. Contact us through our help center at help.openai.com if you continue to have issues. Please add a payment method to your account to increase your rate limit. Visit https://platform.openai.com/account/billing to add a payment method.",        "type": "requests",        "param": null,        "code": null    }}
```

[Local Message] 警告，线程11在执行过程中遭遇问题, Traceback：

```
Traceback (most recent call last):
  File "C:\Users\Tomoyo\Downloads\chatgpt_academic-master\crazy_functions\crazy_utils.py", line 186, in _req_gpt
    gpt_say = predict_no_ui_long_connection(
              ^^^^^^^^^^^^^^^^^^^^^^^^^^^^^^
  File "C:\Users\Tomoyo\Downloads\chatgpt_academic-master\request_llm\bridge_chatgpt.py", line 85, in predict_no_ui_long_connection
    raise RuntimeError("OpenAI拒绝了请求：" + error_msg)
RuntimeError: OpenAI拒绝了请求：{    "error": {        "message": "Rate limit reached for default-gpt-3.5-turbo in organization org-rPNvSW70tLGxHIiUZV8ERzxN on requests per min. Limit: 3 / min. Please try again in 20s. Contact us through our help center at help.openai.com if you continue to have issues. Please add a payment method to your account to increase your rate limit. Visit https://platform.openai.com/account/billing to add a payment method.",        "type": "requests",        "param": null,        "code": null    }}
```

[Local Message] 警告，线程11在执行过程中遭遇问题, Traceback：

```
Traceback (most recent call last):
  File "C:\Users\Tomoyo\Downloads\chatgpt_academic-master\crazy_functions\crazy_utils.py", line 186, in _req_gpt
    gpt_say = predict_no_ui_long_connection(
              ^^^^^^^^^^^^^^^^^^^^^^^^^^^^^^
  File "C:\Users\Tomoyo\Downloads\chatgpt_academic-master\request_llm\bridge_chatgpt.py", line 85, in predict_no_ui_long_connection
    raise RuntimeError("OpenAI拒绝了请求：" + error_msg)
RuntimeError: OpenAI拒绝了请求：{    "error": {        "message": "Rate limit reached for default-gpt-3.5-turbo in organization org-rPNvSW70tLGxHIiUZV8ERzxN on requests per min. Limit: 3 / min. Please try again in 20s. Contact us through our help center at help.openai.com if you continue to have issues. Please add a payment method to your account to increase your rate limit. Visit https://platform.openai.com/account/billing to add a payment method.",        "type": "requests",        "param": null,        "code": null    }}
```



## [12/14] 请对下面的程序文件做一个概述: C:\Users\Tomoyo\Desktop\lxh\service\impl\TeacherServiceImpl.java

本文件是一个Java类文件，位于com.system.service.impl包下。这是一个Service层的实现类，实现了TeacherService接口。通过注解@Service表明它是一个Service层的组件。它主要包含了一些方法实现，包括按照分页查找教师信息、插入、删除和更新教师信息等，并注入了几个Mapper层的组件。同时这个类也抛出了一个自定义异常。

## [13/14] 请对下面的程序文件做一个概述: C:\Users\Tomoyo\Desktop\lxh\service\impl\UserloginServiceImpl.java

[Local Message] 警告，线程13在执行过程中遭遇问题, Traceback：

```
Traceback (most recent call last):
  File "C:\Users\Tomoyo\Downloads\chatgpt_academic-master\crazy_functions\crazy_utils.py", line 186, in _req_gpt
    gpt_say = predict_no_ui_long_connection(
              ^^^^^^^^^^^^^^^^^^^^^^^^^^^^^^
  File "C:\Users\Tomoyo\Downloads\chatgpt_academic-master\request_llm\bridge_chatgpt.py", line 85, in predict_no_ui_long_connection
    raise RuntimeError("OpenAI拒绝了请求：" + error_msg)
RuntimeError: OpenAI拒绝了请求：{    "error": {        "message": "Rate limit reached for default-gpt-3.5-turbo in organization org-rPNvSW70tLGxHIiUZV8ERzxN on requests per min. Limit: 3 / min. Please try again in 20s. Contact us through our help center at help.openai.com if you continue to have issues. Please add a payment method to your account to increase your rate limit. Visit https://platform.openai.com/account/billing to add a payment method.",        "type": "requests",        "param": null,        "code": null    }}
```

[Local Message] 警告，线程13在执行过程中遭遇问题, Traceback：

```
Traceback (most recent call last):
  File "C:\Users\Tomoyo\Downloads\chatgpt_academic-master\crazy_functions\crazy_utils.py", line 186, in _req_gpt
    gpt_say = predict_no_ui_long_connection(
              ^^^^^^^^^^^^^^^^^^^^^^^^^^^^^^
  File "C:\Users\Tomoyo\Downloads\chatgpt_academic-master\request_llm\bridge_chatgpt.py", line 85, in predict_no_ui_long_connection
    raise RuntimeError("OpenAI拒绝了请求：" + error_msg)
RuntimeError: OpenAI拒绝了请求：{    "error": {        "message": "Rate limit reached for default-gpt-3.5-turbo in organization org-rPNvSW70tLGxHIiUZV8ERzxN on requests per min. Limit: 3 / min. Please try again in 20s. Contact us through our help center at help.openai.com if you continue to have issues. Please add a payment method to your account to increase your rate limit. Visit https://platform.openai.com/account/billing to add a payment method.",        "type": "requests",        "param": null,        "code": null    }}
```

[Local Message] 警告，线程13在执行过程中遭遇问题, Traceback：

```
Traceback (most recent call last):
  File "C:\ProgramData\Anaconda3\envs\gptac_venv\Lib\site-packages\urllib3\connectionpool.py", line 703, in urlopen
    httplib_response = self._make_request(
                       ^^^^^^^^^^^^^^^^^^^
  File "C:\ProgramData\Anaconda3\envs\gptac_venv\Lib\site-packages\urllib3\connectionpool.py", line 386, in _make_request
    self._validate_conn(conn)
  File "C:\ProgramData\Anaconda3\envs\gptac_venv\Lib\site-packages\urllib3\connectionpool.py", line 1042, in _validate_conn
    conn.connect()
  File "C:\ProgramData\Anaconda3\envs\gptac_venv\Lib\site-packages\urllib3\connection.py", line 419, in connect
    self.sock = ssl_wrap_socket(
                ^^^^^^^^^^^^^^^^
  File "C:\ProgramData\Anaconda3\envs\gptac_venv\Lib\site-packages\urllib3\util\ssl_.py", line 449, in ssl_wrap_socket
    ssl_sock = _ssl_wrap_socket_impl(
               ^^^^^^^^^^^^^^^^^^^^^^
  File "C:\ProgramData\Anaconda3\envs\gptac_venv\Lib\site-packages\urllib3\util\ssl_.py", line 493, in _ssl_wrap_socket_impl
    return ssl_context.wrap_socket(sock, server_hostname=server_hostname)
           ^^^^^^^^^^^^^^^^^^^^^^^^^^^^^^^^^^^^^^^^^^^^^^^^^^^^^^^^^^^^^^
  File "C:\ProgramData\Anaconda3\envs\gptac_venv\Lib\ssl.py", line 517, in wrap_socket
    return self.sslsocket_class._create(
           ^^^^^^^^^^^^^^^^^^^^^^^^^^^^^
  File "C:\ProgramData\Anaconda3\envs\gptac_venv\Lib\ssl.py", line 1075, in _create
    self.do_handshake()
  File "C:\ProgramData\Anaconda3\envs\gptac_venv\Lib\ssl.py", line 1346, in do_handshake
    self._sslobj.do_handshake()
ssl.SSLEOFError: [SSL: UNEXPECTED_EOF_WHILE_READING] EOF occurred in violation of protocol (_ssl.c:1002)

During handling of the above exception, another exception occurred:

Traceback (most recent call last):
  File "C:\ProgramData\Anaconda3\envs\gptac_venv\Lib\site-packages\requests\adapters.py", line 489, in send
    resp = conn.urlopen(
           ^^^^^^^^^^^^^
  File "C:\ProgramData\Anaconda3\envs\gptac_venv\Lib\site-packages\urllib3\connectionpool.py", line 787, in urlopen
    retries = retries.increment(
              ^^^^^^^^^^^^^^^^^^
  File "C:\ProgramData\Anaconda3\envs\gptac_venv\Lib\site-packages\urllib3\util\retry.py", line 592, in increment
    raise MaxRetryError(_pool, url, error or ResponseError(cause))
urllib3.exceptions.MaxRetryError: SOCKSHTTPSConnectionPool(host='api.openai.com', port=443): Max retries exceeded with url: /v1/chat/completions (Caused by SSLError(SSLEOFError(8, '[SSL: UNEXPECTED_EOF_WHILE_READING] EOF occurred in violation of protocol (_ssl.c:1002)')))

During handling of the above exception, another exception occurred:

Traceback (most recent call last):
  File "C:\Users\Tomoyo\Downloads\chatgpt_academic-master\crazy_functions\crazy_utils.py", line 186, in _req_gpt
    gpt_say = predict_no_ui_long_connection(
              ^^^^^^^^^^^^^^^^^^^^^^^^^^^^^^
  File "C:\Users\Tomoyo\Downloads\chatgpt_academic-master\request_llm\bridge_chatgpt.py", line 63, in predict_no_ui_long_connection
    response = requests.post(API_URL, headers=headers, proxies=proxies,
               ^^^^^^^^^^^^^^^^^^^^^^^^^^^^^^^^^^^^^^^^^^^^^^^^^^^^^^^^
  File "C:\ProgramData\Anaconda3\envs\gptac_venv\Lib\site-packages\requests\api.py", line 115, in post
    return request("post", url, data=data, json=json, **kwargs)
           ^^^^^^^^^^^^^^^^^^^^^^^^^^^^^^^^^^^^^^^^^^^^^^^^^^^^
  File "C:\ProgramData\Anaconda3\envs\gptac_venv\Lib\site-packages\requests\api.py", line 59, in request
    return session.request(method=method, url=url, **kwargs)
           ^^^^^^^^^^^^^^^^^^^^^^^^^^^^^^^^^^^^^^^^^^^^^^^^^
  File "C:\ProgramData\Anaconda3\envs\gptac_venv\Lib\site-packages\requests\sessions.py", line 587, in request
    resp = self.send(prep, **send_kwargs)
           ^^^^^^^^^^^^^^^^^^^^^^^^^^^^^^
  File "C:\ProgramData\Anaconda3\envs\gptac_venv\Lib\site-packages\requests\sessions.py", line 701, in send
    r = adapter.send(request, **kwargs)
        ^^^^^^^^^^^^^^^^^^^^^^^^^^^^^^^
  File "C:\ProgramData\Anaconda3\envs\gptac_venv\Lib\site-packages\requests\adapters.py", line 563, in send
    raise SSLError(e, request=request)
requests.exceptions.SSLError: SOCKSHTTPSConnectionPool(host='api.openai.com', port=443): Max retries exceeded with url: /v1/chat/completions (Caused by SSLError(SSLEOFError(8, '[SSL: UNEXPECTED_EOF_WHILE_READING] EOF occurred in violation of protocol (_ssl.c:1002)')))
```



## 根据以上分析，对程序的整体功能和构架重新做出概括。然后用一张markdown表格整理每个文件的功能（包括service\CollegeService.java, service\CourseService.java, service\RoleService.java, service\SelectedCourseService.java, service\StudentService.java, service\TeacherService.java, service\UserloginService.java, service\impl\CollegeServiceImpl.java, service\impl\CourseServiceImpl.java, service\impl\RoleServiceImpl.java, service\impl\SelectedCourseServiceImpl.java, service\impl\StudentServiceImpl.java, service\impl\TeacherServiceImpl.java, service\impl\UserloginServiceImpl.java）。

根据以上分析，该程序是一个学校课程管理系统。根据每个文件的命名和分析，我们可以将每个文件的功能总结如下：

| 文件名 | 功能 |
| --- | --- |
| CollegeService.java | 对学院信息进行增删改查的方法 |
| CourseService.java | 对课程信息进行增删改查的方法 |
| RoleService.java | 对用户角色信息进行增删改查的方法 |
| SelectedCourseService.java | 对学生选课信息进行增删改查的方法 |
| StudentService.java | 对学生信息进行增删改查的方法 |
| TeacherService.java | 对教师信息进行增删改查的方法 |
| UserloginService.java | 处理用户登录相关的方法 |
| CollegeServiceImpl.java | 实现了CollegeService接口，具体实现了对学院信息进行增删改查的方法 |
| CourseServiceImpl.java | 实现了CourseService接口，具体实现了对课程信息进行增删改查的方法 |
| RoleServiceImpl.java | 实现了RoleService接口，具体实现了对用户角色信息进行增删改查的方法 |
| SelectedCourseServiceImpl.java | 实现了SelectedCourseService接口，具体实现了对学生选课信息进行增删改查的方法 |
| StudentServiceImpl.java | 实现了StudentService接口，具体实现了对学生信息进行增删改查的方法 |
| TeacherServiceImpl.java | 实现了TeacherService接口，具体实现了对教师信息进行增删改查的方法 |
| UserloginServiceImpl.java | 实现了UserloginService接口，具体实现了处理用户登录相关的方法 |

