# chatGPT 分析报告
## 接下来请你逐文件分析下面的工程[0/10] 请对下面的程序文件做一个概述: C:\Users\Tomoyo\Desktop\lxh\system(1)\mapper\CourseMapperCustomTest.java

该文件为Java源代码文件，属于Java Web项目中的持久层（DAO）代码，主要是对Course的数据访问进行测试。该文件中定义了CourseMapperCustomTest类，该类包含了两个方法：setUp和findByPaging，其中setUp方法用于初始化测试环境，findByPaging方法用于测试通过分页查询所有的课程信息。该文件通过调用CourseMapperCustom接口中的方法，实现了对Course表的数据操作。

## [1/10] 请对下面的程序文件做一个概述: C:\Users\Tomoyo\Desktop\lxh\system(1)\mapper\StudentMapperCustomTest.java

[Local Message] 警告，线程1在执行过程中遭遇问题, Traceback：

```
Traceback (most recent call last):
  File "C:\Users\Tomoyo\Downloads\chatgpt_academic-master\crazy_functions\crazy_utils.py", line 186, in _req_gpt
    gpt_say = predict_no_ui_long_connection(
              ^^^^^^^^^^^^^^^^^^^^^^^^^^^^^^
  File "C:\Users\Tomoyo\Downloads\chatgpt_academic-master\request_llm\bridge_chatgpt.py", line 85, in predict_no_ui_long_connection
    raise RuntimeError("OpenAI拒绝了请求：" + error_msg)
RuntimeError: OpenAI拒绝了请求：{    "error": {        "message": "Rate limit reached for default-gpt-3.5-turbo in organization org-rPNvSW70tLGxHIiUZV8ERzxN on requests per min. Limit: 3 / min. Please try again in 20s. Contact us through our help center at help.openai.com if you continue to have issues. Please add a payment method to your account to increase your rate limit. Visit https://platform.openai.com/account/billing to add a payment method.",        "type": "requests",        "param": null,        "code": null    }}
```

[Local Message] 警告，线程1在执行过程中遭遇问题, Traceback：

```
Traceback (most recent call last):
  File "C:\Users\Tomoyo\Downloads\chatgpt_academic-master\crazy_functions\crazy_utils.py", line 186, in _req_gpt
    gpt_say = predict_no_ui_long_connection(
              ^^^^^^^^^^^^^^^^^^^^^^^^^^^^^^
  File "C:\Users\Tomoyo\Downloads\chatgpt_academic-master\request_llm\bridge_chatgpt.py", line 85, in predict_no_ui_long_connection
    raise RuntimeError("OpenAI拒绝了请求：" + error_msg)
RuntimeError: OpenAI拒绝了请求：{    "error": {        "message": "Rate limit reached for default-gpt-3.5-turbo in organization org-rPNvSW70tLGxHIiUZV8ERzxN on requests per min. Limit: 3 / min. Please try again in 20s. Contact us through our help center at help.openai.com if you continue to have issues. Please add a payment method to your account to increase your rate limit. Visit https://platform.openai.com/account/billing to add a payment method.",        "type": "requests",        "param": null,        "code": null    }}
```

[Local Message] 警告，线程1在执行过程中遭遇问题, Traceback：

```
Traceback (most recent call last):
  File "C:\Users\Tomoyo\Downloads\chatgpt_academic-master\crazy_functions\crazy_utils.py", line 186, in _req_gpt
    gpt_say = predict_no_ui_long_connection(
              ^^^^^^^^^^^^^^^^^^^^^^^^^^^^^^
  File "C:\Users\Tomoyo\Downloads\chatgpt_academic-master\request_llm\bridge_chatgpt.py", line 85, in predict_no_ui_long_connection
    raise RuntimeError("OpenAI拒绝了请求：" + error_msg)
RuntimeError: OpenAI拒绝了请求：{    "error": {        "message": "Rate limit reached for default-gpt-3.5-turbo in organization org-rPNvSW70tLGxHIiUZV8ERzxN on requests per min. Limit: 3 / min. Please try again in 20s. Contact us through our help center at help.openai.com if you continue to have issues. Please add a payment method to your account to increase your rate limit. Visit https://platform.openai.com/account/billing to add a payment method.",        "type": "requests",        "param": null,        "code": null    }}
```



## [2/10] 请对下面的程序文件做一个概述: C:\Users\Tomoyo\Desktop\lxh\system(1)\mapper\StudentMapperTest.java

该文件是一个 Java 类文件，位于 com.system.mapper 包下，命名为 StudentMapperTest。该类通过使用 Spring 框架中的 ApplicationContext 容器来获取并测试 StudentMapper 对象中的 selectByExample 方法。在方法中，该类使用自定义条件查询对象 StudentExample 和自定义查询条件（在该例子中是 username 包含“小”的学生）来进行查询，并将结果输出到控制台。

## [3/10] 请对下面的程序文件做一个概述: C:\Users\Tomoyo\Desktop\lxh\system(1)\mapper\TeacherMapperCustomTest.java

[Local Message] 警告，线程3在执行过程中遭遇问题, Traceback：

```
Traceback (most recent call last):
  File "C:\ProgramData\Anaconda3\envs\gptac_venv\Lib\site-packages\urllib3\connectionpool.py", line 703, in urlopen
    httplib_response = self._make_request(
                       ^^^^^^^^^^^^^^^^^^^
  File "C:\ProgramData\Anaconda3\envs\gptac_venv\Lib\site-packages\urllib3\connectionpool.py", line 386, in _make_request
    self._validate_conn(conn)
  File "C:\ProgramData\Anaconda3\envs\gptac_venv\Lib\site-packages\urllib3\connectionpool.py", line 1042, in _validate_conn
    conn.connect()
  File "C:\ProgramData\Anaconda3\envs\gptac_venv\Lib\site-packages\urllib3\connection.py", line 419, in connect
    self.sock = ssl_wrap_socket(
                ^^^^^^^^^^^^^^^^
  File "C:\ProgramData\Anaconda3\envs\gptac_venv\Lib\site-packages\urllib3\util\ssl_.py", line 449, in ssl_wrap_socket
    ssl_sock = _ssl_wrap_socket_impl(
               ^^^^^^^^^^^^^^^^^^^^^^
  File "C:\ProgramData\Anaconda3\envs\gptac_venv\Lib\site-packages\urllib3\util\ssl_.py", line 493, in _ssl_wrap_socket_impl
    return ssl_context.wrap_socket(sock, server_hostname=server_hostname)
           ^^^^^^^^^^^^^^^^^^^^^^^^^^^^^^^^^^^^^^^^^^^^^^^^^^^^^^^^^^^^^^
  File "C:\ProgramData\Anaconda3\envs\gptac_venv\Lib\ssl.py", line 517, in wrap_socket
    return self.sslsocket_class._create(
           ^^^^^^^^^^^^^^^^^^^^^^^^^^^^^
  File "C:\ProgramData\Anaconda3\envs\gptac_venv\Lib\ssl.py", line 1075, in _create
    self.do_handshake()
  File "C:\ProgramData\Anaconda3\envs\gptac_venv\Lib\ssl.py", line 1346, in do_handshake
    self._sslobj.do_handshake()
ConnectionResetError: [WinError 10054] 远程主机强迫关闭了一个现有的连接。

During handling of the above exception, another exception occurred:

Traceback (most recent call last):
  File "C:\ProgramData\Anaconda3\envs\gptac_venv\Lib\site-packages\requests\adapters.py", line 489, in send
    resp = conn.urlopen(
           ^^^^^^^^^^^^^
  File "C:\ProgramData\Anaconda3\envs\gptac_venv\Lib\site-packages\urllib3\connectionpool.py", line 787, in urlopen
    retries = retries.increment(
              ^^^^^^^^^^^^^^^^^^
  File "C:\ProgramData\Anaconda3\envs\gptac_venv\Lib\site-packages\urllib3\util\retry.py", line 550, in increment
    raise six.reraise(type(error), error, _stacktrace)
          ^^^^^^^^^^^^^^^^^^^^^^^^^^^^^^^^^^^^^^^^^^^^
  File "C:\ProgramData\Anaconda3\envs\gptac_venv\Lib\site-packages\urllib3\packages\six.py", line 769, in reraise
    raise value.with_traceback(tb)
  File "C:\ProgramData\Anaconda3\envs\gptac_venv\Lib\site-packages\urllib3\connectionpool.py", line 703, in urlopen
    httplib_response = self._make_request(
                       ^^^^^^^^^^^^^^^^^^^
  File "C:\ProgramData\Anaconda3\envs\gptac_venv\Lib\site-packages\urllib3\connectionpool.py", line 386, in _make_request
    self._validate_conn(conn)
  File "C:\ProgramData\Anaconda3\envs\gptac_venv\Lib\site-packages\urllib3\connectionpool.py", line 1042, in _validate_conn
    conn.connect()
  File "C:\ProgramData\Anaconda3\envs\gptac_venv\Lib\site-packages\urllib3\connection.py", line 419, in connect
    self.sock = ssl_wrap_socket(
                ^^^^^^^^^^^^^^^^
  File "C:\ProgramData\Anaconda3\envs\gptac_venv\Lib\site-packages\urllib3\util\ssl_.py", line 449, in ssl_wrap_socket
    ssl_sock = _ssl_wrap_socket_impl(
               ^^^^^^^^^^^^^^^^^^^^^^
  File "C:\ProgramData\Anaconda3\envs\gptac_venv\Lib\site-packages\urllib3\util\ssl_.py", line 493, in _ssl_wrap_socket_impl
    return ssl_context.wrap_socket(sock, server_hostname=server_hostname)
           ^^^^^^^^^^^^^^^^^^^^^^^^^^^^^^^^^^^^^^^^^^^^^^^^^^^^^^^^^^^^^^
  File "C:\ProgramData\Anaconda3\envs\gptac_venv\Lib\ssl.py", line 517, in wrap_socket
    return self.sslsocket_class._create(
           ^^^^^^^^^^^^^^^^^^^^^^^^^^^^^
  File "C:\ProgramData\Anaconda3\envs\gptac_venv\Lib\ssl.py", line 1075, in _create
    self.do_handshake()
  File "C:\ProgramData\Anaconda3\envs\gptac_venv\Lib\ssl.py", line 1346, in do_handshake
    self._sslobj.do_handshake()
urllib3.exceptions.ProtocolError: ('Connection aborted.', ConnectionResetError(10054, '远程主机强迫关闭了一个现有的连接。', None, 10054, None))

During handling of the above exception, another exception occurred:

Traceback (most recent call last):
  File "C:\Users\Tomoyo\Downloads\chatgpt_academic-master\crazy_functions\crazy_utils.py", line 186, in _req_gpt
    gpt_say = predict_no_ui_long_connection(
              ^^^^^^^^^^^^^^^^^^^^^^^^^^^^^^
  File "C:\Users\Tomoyo\Downloads\chatgpt_academic-master\request_llm\bridge_chatgpt.py", line 63, in predict_no_ui_long_connection
    response = requests.post(API_URL, headers=headers, proxies=proxies,
               ^^^^^^^^^^^^^^^^^^^^^^^^^^^^^^^^^^^^^^^^^^^^^^^^^^^^^^^^
  File "C:\ProgramData\Anaconda3\envs\gptac_venv\Lib\site-packages\requests\api.py", line 115, in post
    return request("post", url, data=data, json=json, **kwargs)
           ^^^^^^^^^^^^^^^^^^^^^^^^^^^^^^^^^^^^^^^^^^^^^^^^^^^^
  File "C:\ProgramData\Anaconda3\envs\gptac_venv\Lib\site-packages\requests\api.py", line 59, in request
    return session.request(method=method, url=url, **kwargs)
           ^^^^^^^^^^^^^^^^^^^^^^^^^^^^^^^^^^^^^^^^^^^^^^^^^
  File "C:\ProgramData\Anaconda3\envs\gptac_venv\Lib\site-packages\requests\sessions.py", line 587, in request
    resp = self.send(prep, **send_kwargs)
           ^^^^^^^^^^^^^^^^^^^^^^^^^^^^^^
  File "C:\ProgramData\Anaconda3\envs\gptac_venv\Lib\site-packages\requests\sessions.py", line 701, in send
    r = adapter.send(request, **kwargs)
        ^^^^^^^^^^^^^^^^^^^^^^^^^^^^^^^
  File "C:\ProgramData\Anaconda3\envs\gptac_venv\Lib\site-packages\requests\adapters.py", line 547, in send
    raise ConnectionError(err, request=request)
requests.exceptions.ConnectionError: ('Connection aborted.', ConnectionResetError(10054, '远程主机强迫关闭了一个现有的连接。', None, 10054, None))
```

[Local Message] 警告，线程3在执行过程中遭遇问题, Traceback：

```
Traceback (most recent call last):
  File "C:\Users\Tomoyo\Downloads\chatgpt_academic-master\crazy_functions\crazy_utils.py", line 186, in _req_gpt
    gpt_say = predict_no_ui_long_connection(
              ^^^^^^^^^^^^^^^^^^^^^^^^^^^^^^
  File "C:\Users\Tomoyo\Downloads\chatgpt_academic-master\request_llm\bridge_chatgpt.py", line 85, in predict_no_ui_long_connection
    raise RuntimeError("OpenAI拒绝了请求：" + error_msg)
RuntimeError: OpenAI拒绝了请求：{    "error": {        "message": "Rate limit reached for default-gpt-3.5-turbo in organization org-rPNvSW70tLGxHIiUZV8ERzxN on requests per min. Limit: 3 / min. Please try again in 20s. Contact us through our help center at help.openai.com if you continue to have issues. Please add a payment method to your account to increase your rate limit. Visit https://platform.openai.com/account/billing to add a payment method.",        "type": "requests",        "param": null,        "code": null    }}
```

[Local Message] 警告，线程3在执行过程中遭遇问题, Traceback：

```
Traceback (most recent call last):
  File "C:\Users\Tomoyo\Downloads\chatgpt_academic-master\crazy_functions\crazy_utils.py", line 186, in _req_gpt
    gpt_say = predict_no_ui_long_connection(
              ^^^^^^^^^^^^^^^^^^^^^^^^^^^^^^
  File "C:\Users\Tomoyo\Downloads\chatgpt_academic-master\request_llm\bridge_chatgpt.py", line 85, in predict_no_ui_long_connection
    raise RuntimeError("OpenAI拒绝了请求：" + error_msg)
RuntimeError: OpenAI拒绝了请求：{    "error": {        "message": "Rate limit reached for default-gpt-3.5-turbo in organization org-rPNvSW70tLGxHIiUZV8ERzxN on requests per min. Limit: 3 / min. Please try again in 20s. Contact us through our help center at help.openai.com if you continue to have issues. Please add a payment method to your account to increase your rate limit. Visit https://platform.openai.com/account/billing to add a payment method.",        "type": "requests",        "param": null,        "code": null    }}
```



## [4/10] 请对下面的程序文件做一个概述: C:\Users\Tomoyo\Desktop\lxh\system(1)\mapper\UserloginMapperCustomTest.java

[Local Message] 警告，线程4在执行过程中遭遇问题, Traceback：

```
Traceback (most recent call last):
  File "C:\Users\Tomoyo\Downloads\chatgpt_academic-master\crazy_functions\crazy_utils.py", line 186, in _req_gpt
    gpt_say = predict_no_ui_long_connection(
              ^^^^^^^^^^^^^^^^^^^^^^^^^^^^^^
  File "C:\Users\Tomoyo\Downloads\chatgpt_academic-master\request_llm\bridge_chatgpt.py", line 85, in predict_no_ui_long_connection
    raise RuntimeError("OpenAI拒绝了请求：" + error_msg)
RuntimeError: OpenAI拒绝了请求：{    "error": {        "message": "Rate limit reached for default-gpt-3.5-turbo in organization org-rPNvSW70tLGxHIiUZV8ERzxN on requests per min. Limit: 3 / min. Please try again in 20s. Contact us through our help center at help.openai.com if you continue to have issues. Please add a payment method to your account to increase your rate limit. Visit https://platform.openai.com/account/billing to add a payment method.",        "type": "requests",        "param": null,        "code": null    }}
```

[Local Message] 警告，线程4在执行过程中遭遇问题, Traceback：

```
Traceback (most recent call last):
  File "C:\Users\Tomoyo\Downloads\chatgpt_academic-master\crazy_functions\crazy_utils.py", line 186, in _req_gpt
    gpt_say = predict_no_ui_long_connection(
              ^^^^^^^^^^^^^^^^^^^^^^^^^^^^^^
  File "C:\Users\Tomoyo\Downloads\chatgpt_academic-master\request_llm\bridge_chatgpt.py", line 85, in predict_no_ui_long_connection
    raise RuntimeError("OpenAI拒绝了请求：" + error_msg)
RuntimeError: OpenAI拒绝了请求：{    "error": {        "message": "Rate limit reached for default-gpt-3.5-turbo in organization org-rPNvSW70tLGxHIiUZV8ERzxN on requests per min. Limit: 3 / min. Please try again in 20s. Contact us through our help center at help.openai.com if you continue to have issues. Please add a payment method to your account to increase your rate limit. Visit https://platform.openai.com/account/billing to add a payment method.",        "type": "requests",        "param": null,        "code": null    }}
```

[Local Message] 警告，线程4在执行过程中遭遇问题, Traceback：

```
Traceback (most recent call last):
  File "C:\Users\Tomoyo\Downloads\chatgpt_academic-master\crazy_functions\crazy_utils.py", line 186, in _req_gpt
    gpt_say = predict_no_ui_long_connection(
              ^^^^^^^^^^^^^^^^^^^^^^^^^^^^^^
  File "C:\Users\Tomoyo\Downloads\chatgpt_academic-master\request_llm\bridge_chatgpt.py", line 85, in predict_no_ui_long_connection
    raise RuntimeError("OpenAI拒绝了请求：" + error_msg)
RuntimeError: OpenAI拒绝了请求：{    "error": {        "message": "Rate limit reached for default-gpt-3.5-turbo in organization org-rPNvSW70tLGxHIiUZV8ERzxN on requests per min. Limit: 3 / min. Please try again in 20s. Contact us through our help center at help.openai.com if you continue to have issues. Please add a payment method to your account to increase your rate limit. Visit https://platform.openai.com/account/billing to add a payment method.",        "type": "requests",        "param": null,        "code": null    }}
```



## [5/10] 请对下面的程序文件做一个概述: C:\Users\Tomoyo\Desktop\lxh\system(1)\service\impl\CourseServiceImplTest.java

[Local Message] 警告，线程5在执行过程中遭遇问题, Traceback：

```
Traceback (most recent call last):
  File "C:\Users\Tomoyo\Downloads\chatgpt_academic-master\crazy_functions\crazy_utils.py", line 186, in _req_gpt
    gpt_say = predict_no_ui_long_connection(
              ^^^^^^^^^^^^^^^^^^^^^^^^^^^^^^
  File "C:\Users\Tomoyo\Downloads\chatgpt_academic-master\request_llm\bridge_chatgpt.py", line 85, in predict_no_ui_long_connection
    raise RuntimeError("OpenAI拒绝了请求：" + error_msg)
RuntimeError: OpenAI拒绝了请求：{    "error": {        "message": "Rate limit reached for default-gpt-3.5-turbo in organization org-rPNvSW70tLGxHIiUZV8ERzxN on requests per min. Limit: 3 / min. Please try again in 20s. Contact us through our help center at help.openai.com if you continue to have issues. Please add a payment method to your account to increase your rate limit. Visit https://platform.openai.com/account/billing to add a payment method.",        "type": "requests",        "param": null,        "code": null    }}
```

[Local Message] 警告，线程5在执行过程中遭遇问题, Traceback：

```
Traceback (most recent call last):
  File "C:\Users\Tomoyo\Downloads\chatgpt_academic-master\crazy_functions\crazy_utils.py", line 186, in _req_gpt
    gpt_say = predict_no_ui_long_connection(
              ^^^^^^^^^^^^^^^^^^^^^^^^^^^^^^
  File "C:\Users\Tomoyo\Downloads\chatgpt_academic-master\request_llm\bridge_chatgpt.py", line 85, in predict_no_ui_long_connection
    raise RuntimeError("OpenAI拒绝了请求：" + error_msg)
RuntimeError: OpenAI拒绝了请求：{    "error": {        "message": "Rate limit reached for default-gpt-3.5-turbo in organization org-rPNvSW70tLGxHIiUZV8ERzxN on requests per min. Limit: 3 / min. Please try again in 20s. Contact us through our help center at help.openai.com if you continue to have issues. Please add a payment method to your account to increase your rate limit. Visit https://platform.openai.com/account/billing to add a payment method.",        "type": "requests",        "param": null,        "code": null    }}
```

[Local Message] 警告，线程5在执行过程中遭遇问题, Traceback：

```
Traceback (most recent call last):
  File "C:\Users\Tomoyo\Downloads\chatgpt_academic-master\crazy_functions\crazy_utils.py", line 186, in _req_gpt
    gpt_say = predict_no_ui_long_connection(
              ^^^^^^^^^^^^^^^^^^^^^^^^^^^^^^
  File "C:\Users\Tomoyo\Downloads\chatgpt_academic-master\request_llm\bridge_chatgpt.py", line 85, in predict_no_ui_long_connection
    raise RuntimeError("OpenAI拒绝了请求：" + error_msg)
RuntimeError: OpenAI拒绝了请求：{    "error": {        "message": "Rate limit reached for default-gpt-3.5-turbo in organization org-rPNvSW70tLGxHIiUZV8ERzxN on requests per min. Limit: 3 / min. Please try again in 20s. Contact us through our help center at help.openai.com if you continue to have issues. Please add a payment method to your account to increase your rate limit. Visit https://platform.openai.com/account/billing to add a payment method.",        "type": "requests",        "param": null,        "code": null    }}
```



## [6/10] 请对下面的程序文件做一个概述: C:\Users\Tomoyo\Desktop\lxh\system(1)\service\impl\SelectedCourseServiceImplTest.java

这是一个名为"SelectedCourseServiceImplTest.java"的Java文件，位于"com.system.service.impl"包中。这个文件包含了一个测试用例类，名为"SelectedCourseServiceImplTest"。这个测试用例对应于"SelectedCourseServiceImpl"类中的"findByCourseID"方法，并验证了在该方法中是否能正确地查询数据库并返回相应数据。在测试用例中引入了一些类、方法和框架，如"SelectedCourseCustom"类、"CourseService"接口、"ApplicationContext"接口、"ClassPathXmlApplicationContext"类等。

## [7/10] 请对下面的程序文件做一个概述: C:\Users\Tomoyo\Desktop\lxh\system(1)\service\impl\StudentServiceImplTest.java

[Local Message] 警告，线程7在执行过程中遭遇问题, Traceback：

```
Traceback (most recent call last):
  File "C:\Users\Tomoyo\Downloads\chatgpt_academic-master\crazy_functions\crazy_utils.py", line 186, in _req_gpt
    gpt_say = predict_no_ui_long_connection(
              ^^^^^^^^^^^^^^^^^^^^^^^^^^^^^^
  File "C:\Users\Tomoyo\Downloads\chatgpt_academic-master\request_llm\bridge_chatgpt.py", line 85, in predict_no_ui_long_connection
    raise RuntimeError("OpenAI拒绝了请求：" + error_msg)
RuntimeError: OpenAI拒绝了请求：{    "error": {        "message": "Rate limit reached for default-gpt-3.5-turbo in organization org-rPNvSW70tLGxHIiUZV8ERzxN on requests per min. Limit: 3 / min. Please try again in 20s. Contact us through our help center at help.openai.com if you continue to have issues. Please add a payment method to your account to increase your rate limit. Visit https://platform.openai.com/account/billing to add a payment method.",        "type": "requests",        "param": null,        "code": null    }}
```

[Local Message] 警告，线程7在执行过程中遭遇问题, Traceback：

```
Traceback (most recent call last):
  File "C:\ProgramData\Anaconda3\envs\gptac_venv\Lib\site-packages\urllib3\connectionpool.py", line 703, in urlopen
    httplib_response = self._make_request(
                       ^^^^^^^^^^^^^^^^^^^
  File "C:\ProgramData\Anaconda3\envs\gptac_venv\Lib\site-packages\urllib3\connectionpool.py", line 386, in _make_request
    self._validate_conn(conn)
  File "C:\ProgramData\Anaconda3\envs\gptac_venv\Lib\site-packages\urllib3\connectionpool.py", line 1042, in _validate_conn
    conn.connect()
  File "C:\ProgramData\Anaconda3\envs\gptac_venv\Lib\site-packages\urllib3\connection.py", line 419, in connect
    self.sock = ssl_wrap_socket(
                ^^^^^^^^^^^^^^^^
  File "C:\ProgramData\Anaconda3\envs\gptac_venv\Lib\site-packages\urllib3\util\ssl_.py", line 449, in ssl_wrap_socket
    ssl_sock = _ssl_wrap_socket_impl(
               ^^^^^^^^^^^^^^^^^^^^^^
  File "C:\ProgramData\Anaconda3\envs\gptac_venv\Lib\site-packages\urllib3\util\ssl_.py", line 493, in _ssl_wrap_socket_impl
    return ssl_context.wrap_socket(sock, server_hostname=server_hostname)
           ^^^^^^^^^^^^^^^^^^^^^^^^^^^^^^^^^^^^^^^^^^^^^^^^^^^^^^^^^^^^^^
  File "C:\ProgramData\Anaconda3\envs\gptac_venv\Lib\ssl.py", line 517, in wrap_socket
    return self.sslsocket_class._create(
           ^^^^^^^^^^^^^^^^^^^^^^^^^^^^^
  File "C:\ProgramData\Anaconda3\envs\gptac_venv\Lib\ssl.py", line 1075, in _create
    self.do_handshake()
  File "C:\ProgramData\Anaconda3\envs\gptac_venv\Lib\ssl.py", line 1346, in do_handshake
    self._sslobj.do_handshake()
ConnectionResetError: [WinError 10054] 远程主机强迫关闭了一个现有的连接。

During handling of the above exception, another exception occurred:

Traceback (most recent call last):
  File "C:\ProgramData\Anaconda3\envs\gptac_venv\Lib\site-packages\requests\adapters.py", line 489, in send
    resp = conn.urlopen(
           ^^^^^^^^^^^^^
  File "C:\ProgramData\Anaconda3\envs\gptac_venv\Lib\site-packages\urllib3\connectionpool.py", line 787, in urlopen
    retries = retries.increment(
              ^^^^^^^^^^^^^^^^^^
  File "C:\ProgramData\Anaconda3\envs\gptac_venv\Lib\site-packages\urllib3\util\retry.py", line 550, in increment
    raise six.reraise(type(error), error, _stacktrace)
          ^^^^^^^^^^^^^^^^^^^^^^^^^^^^^^^^^^^^^^^^^^^^
  File "C:\ProgramData\Anaconda3\envs\gptac_venv\Lib\site-packages\urllib3\packages\six.py", line 769, in reraise
    raise value.with_traceback(tb)
  File "C:\ProgramData\Anaconda3\envs\gptac_venv\Lib\site-packages\urllib3\connectionpool.py", line 703, in urlopen
    httplib_response = self._make_request(
                       ^^^^^^^^^^^^^^^^^^^
  File "C:\ProgramData\Anaconda3\envs\gptac_venv\Lib\site-packages\urllib3\connectionpool.py", line 386, in _make_request
    self._validate_conn(conn)
  File "C:\ProgramData\Anaconda3\envs\gptac_venv\Lib\site-packages\urllib3\connectionpool.py", line 1042, in _validate_conn
    conn.connect()
  File "C:\ProgramData\Anaconda3\envs\gptac_venv\Lib\site-packages\urllib3\connection.py", line 419, in connect
    self.sock = ssl_wrap_socket(
                ^^^^^^^^^^^^^^^^
  File "C:\ProgramData\Anaconda3\envs\gptac_venv\Lib\site-packages\urllib3\util\ssl_.py", line 449, in ssl_wrap_socket
    ssl_sock = _ssl_wrap_socket_impl(
               ^^^^^^^^^^^^^^^^^^^^^^
  File "C:\ProgramData\Anaconda3\envs\gptac_venv\Lib\site-packages\urllib3\util\ssl_.py", line 493, in _ssl_wrap_socket_impl
    return ssl_context.wrap_socket(sock, server_hostname=server_hostname)
           ^^^^^^^^^^^^^^^^^^^^^^^^^^^^^^^^^^^^^^^^^^^^^^^^^^^^^^^^^^^^^^
  File "C:\ProgramData\Anaconda3\envs\gptac_venv\Lib\ssl.py", line 517, in wrap_socket
    return self.sslsocket_class._create(
           ^^^^^^^^^^^^^^^^^^^^^^^^^^^^^
  File "C:\ProgramData\Anaconda3\envs\gptac_venv\Lib\ssl.py", line 1075, in _create
    self.do_handshake()
  File "C:\ProgramData\Anaconda3\envs\gptac_venv\Lib\ssl.py", line 1346, in do_handshake
    self._sslobj.do_handshake()
urllib3.exceptions.ProtocolError: ('Connection aborted.', ConnectionResetError(10054, '远程主机强迫关闭了一个现有的连接。', None, 10054, None))

During handling of the above exception, another exception occurred:

Traceback (most recent call last):
  File "C:\Users\Tomoyo\Downloads\chatgpt_academic-master\crazy_functions\crazy_utils.py", line 186, in _req_gpt
    gpt_say = predict_no_ui_long_connection(
              ^^^^^^^^^^^^^^^^^^^^^^^^^^^^^^
  File "C:\Users\Tomoyo\Downloads\chatgpt_academic-master\request_llm\bridge_chatgpt.py", line 63, in predict_no_ui_long_connection
    response = requests.post(API_URL, headers=headers, proxies=proxies,
               ^^^^^^^^^^^^^^^^^^^^^^^^^^^^^^^^^^^^^^^^^^^^^^^^^^^^^^^^
  File "C:\ProgramData\Anaconda3\envs\gptac_venv\Lib\site-packages\requests\api.py", line 115, in post
    return request("post", url, data=data, json=json, **kwargs)
           ^^^^^^^^^^^^^^^^^^^^^^^^^^^^^^^^^^^^^^^^^^^^^^^^^^^^
  File "C:\ProgramData\Anaconda3\envs\gptac_venv\Lib\site-packages\requests\api.py", line 59, in request
    return session.request(method=method, url=url, **kwargs)
           ^^^^^^^^^^^^^^^^^^^^^^^^^^^^^^^^^^^^^^^^^^^^^^^^^
  File "C:\ProgramData\Anaconda3\envs\gptac_venv\Lib\site-packages\requests\sessions.py", line 587, in request
    resp = self.send(prep, **send_kwargs)
           ^^^^^^^^^^^^^^^^^^^^^^^^^^^^^^
  File "C:\ProgramData\Anaconda3\envs\gptac_venv\Lib\site-packages\requests\sessions.py", line 701, in send
    r = adapter.send(request, **kwargs)
        ^^^^^^^^^^^^^^^^^^^^^^^^^^^^^^^
  File "C:\ProgramData\Anaconda3\envs\gptac_venv\Lib\site-packages\requests\adapters.py", line 547, in send
    raise ConnectionError(err, request=request)
requests.exceptions.ConnectionError: ('Connection aborted.', ConnectionResetError(10054, '远程主机强迫关闭了一个现有的连接。', None, 10054, None))
```

[Local Message] 警告，线程7在执行过程中遭遇问题, Traceback：

```
Traceback (most recent call last):
  File "C:\Users\Tomoyo\Downloads\chatgpt_academic-master\crazy_functions\crazy_utils.py", line 186, in _req_gpt
    gpt_say = predict_no_ui_long_connection(
              ^^^^^^^^^^^^^^^^^^^^^^^^^^^^^^
  File "C:\Users\Tomoyo\Downloads\chatgpt_academic-master\request_llm\bridge_chatgpt.py", line 85, in predict_no_ui_long_connection
    raise RuntimeError("OpenAI拒绝了请求：" + error_msg)
RuntimeError: OpenAI拒绝了请求：{    "error": {        "message": "Rate limit reached for default-gpt-3.5-turbo in organization org-rPNvSW70tLGxHIiUZV8ERzxN on requests per min. Limit: 3 / min. Please try again in 20s. Contact us through our help center at help.openai.com if you continue to have issues. Please add a payment method to your account to increase your rate limit. Visit https://platform.openai.com/account/billing to add a payment method.",        "type": "requests",        "param": null,        "code": null    }}
```



## [8/10] 请对下面的程序文件做一个概述: C:\Users\Tomoyo\Desktop\lxh\system(1)\service\impl\TeacherServiceImplTest.java

[Local Message] 警告，线程8在执行过程中遭遇问题, Traceback：

```
Traceback (most recent call last):
  File "C:\Users\Tomoyo\Downloads\chatgpt_academic-master\crazy_functions\crazy_utils.py", line 186, in _req_gpt
    gpt_say = predict_no_ui_long_connection(
              ^^^^^^^^^^^^^^^^^^^^^^^^^^^^^^
  File "C:\Users\Tomoyo\Downloads\chatgpt_academic-master\request_llm\bridge_chatgpt.py", line 85, in predict_no_ui_long_connection
    raise RuntimeError("OpenAI拒绝了请求：" + error_msg)
RuntimeError: OpenAI拒绝了请求：{    "error": {        "message": "Rate limit reached for default-gpt-3.5-turbo in organization org-rPNvSW70tLGxHIiUZV8ERzxN on requests per min. Limit: 3 / min. Please try again in 20s. Contact us through our help center at help.openai.com if you continue to have issues. Please add a payment method to your account to increase your rate limit. Visit https://platform.openai.com/account/billing to add a payment method.",        "type": "requests",        "param": null,        "code": null    }}
```

[Local Message] 警告，线程8在执行过程中遭遇问题, Traceback：

```
Traceback (most recent call last):
  File "C:\Users\Tomoyo\Downloads\chatgpt_academic-master\crazy_functions\crazy_utils.py", line 186, in _req_gpt
    gpt_say = predict_no_ui_long_connection(
              ^^^^^^^^^^^^^^^^^^^^^^^^^^^^^^
  File "C:\Users\Tomoyo\Downloads\chatgpt_academic-master\request_llm\bridge_chatgpt.py", line 85, in predict_no_ui_long_connection
    raise RuntimeError("OpenAI拒绝了请求：" + error_msg)
RuntimeError: OpenAI拒绝了请求：{    "error": {        "message": "Rate limit reached for default-gpt-3.5-turbo in organization org-rPNvSW70tLGxHIiUZV8ERzxN on requests per min. Limit: 3 / min. Please try again in 20s. Contact us through our help center at help.openai.com if you continue to have issues. Please add a payment method to your account to increase your rate limit. Visit https://platform.openai.com/account/billing to add a payment method.",        "type": "requests",        "param": null,        "code": null    }}
```

[Local Message] 警告，线程8在执行过程中遭遇问题, Traceback：

```
Traceback (most recent call last):
  File "C:\Users\Tomoyo\Downloads\chatgpt_academic-master\crazy_functions\crazy_utils.py", line 186, in _req_gpt
    gpt_say = predict_no_ui_long_connection(
              ^^^^^^^^^^^^^^^^^^^^^^^^^^^^^^
  File "C:\Users\Tomoyo\Downloads\chatgpt_academic-master\request_llm\bridge_chatgpt.py", line 85, in predict_no_ui_long_connection
    raise RuntimeError("OpenAI拒绝了请求：" + error_msg)
RuntimeError: OpenAI拒绝了请求：{    "error": {        "message": "Rate limit reached for default-gpt-3.5-turbo in organization org-rPNvSW70tLGxHIiUZV8ERzxN on requests per min. Limit: 3 / min. Please try again in 20s. Contact us through our help center at help.openai.com if you continue to have issues. Please add a payment method to your account to increase your rate limit. Visit https://platform.openai.com/account/billing to add a payment method.",        "type": "requests",        "param": null,        "code": null    }}
```



## [9/10] 请对下面的程序文件做一个概述: C:\Users\Tomoyo\Desktop\lxh\system(1)\service\impl\UserloginServiceImplTest.java

这是一个Java测试文件(system(1)\service\impl\UserloginServiceImplTest.java)，测试了UserloginServiceImpl类中的findByName()方法。它使用了Spring框架的ApplicationContext类，通过该类实例化UserloginServiceImpl并测试其findByName()方法是否正常工作。测试通过后，控制台将输出一个空行。

## 根据以上分析，对程序的整体功能和构架重新做出概括。然后用一张markdown表格整理每个文件的功能（包括system(1)\mapper\CourseMapperCustomTest.java, system(1)\mapper\StudentMapperCustomTest.java, system(1)\mapper\StudentMapperTest.java, system(1)\mapper\TeacherMapperCustomTest.java, system(1)\mapper\UserloginMapperCustomTest.java, system(1)\service\impl\CourseServiceImplTest.java, system(1)\service\impl\SelectedCourseServiceImplTest.java, system(1)\service\impl\StudentServiceImplTest.java, system(1)\service\impl\TeacherServiceImplTest.java, system(1)\service\impl\UserloginServiceImplTest.java）。

根据以上分析，可以得出该程序的整体功能和构架如下：

整体功能：该程序是一个Java Web项目，实现了一个在线教育网站的后端功能。该项目实现了包括学生、教师、课程、选课、登录等功能，通过MyBatis框架实现数据的CRUD操作，通过Spring框架实现依赖注入和控制反转。

构架：

- 数据库：使用Oracle数据库存储数据。
- 持久层：使用MyBatis框架实现数据的CRUD操作。
- 服务层：使用Spring框架实现依赖注入和控制反转。
- 控制层：使用Spring MVC框架实现请求响应。

下表详细列出了每个文件的功能：



文件名 | 功能
--------|-------
CourseMapperCustomTest.java | 测试CourseMapperCustom接口中的数据访问相关方法，测试findByPaging()方法通过分页查询所有的课程信息是否正确。
StudentMapperCustomTest.java | 测试StudentMapperCustom接口中的数据访问相关方法，主要用于对学生信息的操作进行测试。
StudentMapperTest.java | 测试StudentMapper接口中的数据访问相关方法，主要用于对学生信息的操作进行测试。
TeacherMapperCustomTest.java | 测试TeacherMapperCustom接口中的数据访问相关方法，主要用于对教师信息的操作进行测试。
UserloginMapperCustomTest.java | 测试UserloginMapperCustom接口中的数据访问相关方法，主要用于对用户登录信息的操作进行测试。
CourseServiceImplTest.java | 测试CourseServiceImpl类中的业务逻辑相关方法，主要用于对课程信息的操作进行测试。
SelectedCourseServiceImplTest.java | 测试SelectedCourseServiceImpl类中的业务逻辑相关方法，主要用于对选课信息的操作进行测试。
StudentServiceImplTest.java | 测试StudentServiceImpl类中的业务逻辑相关方法，主要用于对学生信息的操作进行测试。
TeacherServiceImplTest.java | 测试TeacherServiceImpl类中的业务逻辑相关方法，主要用于对教师信息的操作进行测试。
UserloginServiceImplTest.java | 测试UserloginServiceImpl类中的业务逻辑相关方法，主要用于对用户登录信息的操作进行测试。

